Workbook
Name MONTHS: #REF!

Sheet EH Staff
A1: SL # | B1: FILE # | C1: EMPLOYEE NAME | D1: POSITION | E1: COMPANY | F1: =TEXT(F2,"DDD") -> Sat | G1: =TEXT(G2,"DDD") -> Sun | H1: =TEXT(H2,"DDD") -> Mon | I1: =TEXT(I2,"DDD") -> Tue | J1: =TEXT(J2,"DDD") -> Wed | K1: =TEXT(K2,"DDD") -> Thu | L1: =TEXT(L2,"DDD") -> Fri | M1: =TEXT(M2,"DDD") -> Sat | ... AJ1: =TEXT(AJ2,"DDD") -> Mon | AL1: =TEXT(AL2,"DDD") -> Tue | AM1: =TEXT(AM2,"DDD") -> Wed | AN1: =TEXT(AN2,"DDD") -> Thu | AO1: =TEXT(AO2,"DDD") -> Fri | AP1: =TEXT(AP2,"DDD") -> Sat | AQ1: =TEXT(AQ2,"DDD") -> Sun | AR1: =TEXT(AR2,"DDD") -> Mon | AS1: =TEXT(AS2,"DDD") -> Tue | ... BP1: =TEXT(BP2,"DDD") | BR1: TOTAL OVERTIME | BS1: TOTAL ABSENT | BT1: REMARKS
F2: ='MONTH SETTING'!G3 -> 46235 | G2: =IF(F2<'MONTH SETTING'!$G$4,F2+1,"") -> 46236 | H2: =IF(G2<'MONTH SETTING'!$G$4,G2+1,"") -> 46237 | I2: =IF(H2<'MONTH SETTING'!$G$4,H2+1,"") -> 46238 | J2: =IF(I2<'MONTH SETTING'!$G$4,I2+1,"") -> 46239 | K2: =IF(J2<'MONTH SETTING'!$G$4,J2+1,"") -> 46240 | L2: =IF(K2<'MONTH SETTING'!$G$4,K2+1,"") -> 46241 | M2: =IF(L2<'MONTH SETTING'!$G$4,L2+1,"") -> 46242 | N2: =IF(M2<'MONTH SETTING'!$G$4,M2+1,"") -> 46243 | ... AJ2: =IF(AI2<'MONTH SETTING'!$G$4,AI2+1,"") -> 46265 | AL2: ='MONTH SETTING'!$G$7 -> 46266 | AM2: =IF(AL2<'MONTH SETTING'!$G$8,AL2+1,"") -> 46267 | AN2: =IF(AM2<'MONTH SETTING'!$G$8,AM2+1,"") -> 46268 | AO2: =IF(AN2<'MONTH SETTING'!$G$8,AN2+1,"") -> 46269 | AP2: =IF(AO2<'MONTH SETTING'!$G$8,AO2+1,"") -> 46270 | AQ2: =IF(AP2<'MONTH SETTING'!$G$8,AP2+1,"") -> 46271 | AR2: =IF(AQ2<'MONTH SETTING'!$G$8,AQ2+1,"") -> 46272 | AS2: =IF(AR2<'MONTH SETTING'!$G$8,AR2+1,"") -> 46273 | AT2: =IF(AS2<'MONTH SETTING'!$G$8,AS2+1,"") -> 46274 | ... BP2: =IF(BO2<'MONTH SETTING'!$G$8,BO2+1,"")
A3: 1 | B3: 2407930680 | C3: LAMBERT CAINGAT MOLINA | D3: ELEC. FOREMAN | E3: EH | X3: 2 | Y3: 2 | AA3: 2 | AB3: 2 | AC3: 2 | AD3: 2 | AE3: 2 | AF3: 2 | AH3: 2 | AI3: 2 | AJ3: 2 | AL3: 2 | AM3: 2 | AN3: 2 | AP3: 2 | BR3: =SUM(R3:BP3) -> 30 | BS3: =COUNTIF(F3:BP3,"A") -> 0
A4: 2 | B4: 2078939747 | C4: HAMADH ISMAIL HASSAN OLAYWA | D4: SENIOR FOREMAN | E4: - | X4: 1 | Y4: 1 | AA4: 1 | AB4: 1 | AC4: 1 | AD4: 1 | AE4: 1 | AF4: 1 | AH4: 1 | AI4: 1 | AJ4: 1 | AL4: 1 | AM4: 1 | AN4: 1 | AP4: 1 | BR4: =SUM(R4:BP4) -> 15 | BS4: =COUNTIF(F4:BP4,"A") -> 0
A5: 3 | B5: 1401 | C5: SYED NISAR MEHDI | D5: DC & ADMN. | E5: EH | BR5: =SUM(R5:BP5) -> 0 | BS5: =COUNTIF(F5:BP5,"A") -> 0 | BT5: Sick Leave
A6: 4 | B6: 2512936473 | C6: MOHAMED ABDELNABI ABURIYA | D6: FINISHING FOREMAN | E6: - | X6: V | Y6: V | AA6: V | AB6: V | AC6: V | AD6: V | AE6: V | AF6: V | AH6: V | AI6: V | AJ6: V | AL6: V | AM6: V | AN6: V | AP6: V | AQ6: V | AR6: V | AS6: V | BR6: =SUM(R6:BP6) -> 0 | BS6: =COUNTIF(F6:BP6,"A") -> 0 | BT6: On Annual Vacation From (09.Aug.2026 to 8.Sep.2026)
A7: 5 | B7: 2377490566 | C7: AHMED SALAHELDIN IBRAHIM | D7: SAFETY SUPERVISOR | E7: - | X7: 1 | Y7: 1 | AA7: 1 | AB7: 1 | AC7: 1 | AD7: 1 | AE7: 1 | AF7: 1 | AH7: 1 | AI7: 1 | AJ7: 1 | AL7: 1 | AM7: 3 | AN7: 1 | AO7: 8 | AP7: 1 | BR7: =SUM(R7:BP7) -> 25 | BS7: =COUNTIF(F7:BP7,"A") -> 0
A8: 6 | B8: 775 | C8: HAZIM GAMAL ALRASHEED | D8: SURVEYOR | E8: EH | X8: 1 | Y8: 1 | AA8: 1 | AB8: 1 | AC8: 1 | AD8: 1 | AE8: 1 | AF8: 1 | AH8: 1 | AI8: 1 | AJ8: 1 | AL8: 1 | AM8: 1 | AN8: 1 | AP8: 1 | BR8: =SUM(R8:BP8) -> 15 | BS8: =COUNTIF(F8:BP8,"A") -> 0
A9: 7 | B9: 2588344990 | C9: IMRAN MUNIR | D9: SURVEYOR | E9: EH | X9: 1 | Y9: 1 | AA9: 1 | AB9: 1 | AC9: 1 | AD9: 1 | AE9: 1 | AF9: 1 | AH9: 1 | AI9: 1 | AJ9: 1 | AL9: 1 | AM9: 1 | AN9: 1 | AO9: 6 | AP9: 1 | BR9: =SUM(R9:BP9) -> 21 | BS9: =COUNTIF(F9:BP9,"A") -> 0
A10: 8 | B10: 2412520922 | C10: RAMADAN RAMADAN ABDELHAMID ELGOHARY | D10: MECHANICAL FOREMAN | E10: EH | X10: 2 | Y10: 2 | AA10: 2 | AB10: 2 | AC10: 2 | AD10: 2 | AE10: 2 | AF10: 2 | AH10: 2 | AI10: 2 | AJ10: 2 | AL10: 2 | AM10: 2 | AN10: 2 | AP10: 2 | BR10: =SUM(R10:BP10) -> 30 | BS10: =COUNTIF(F10:BP10,"A") -> 0
A11: 9 | B11: 2533698649 | C11: IQBAL MOFIZUR RAHMAN | D11: Loader Operator | E11: EH | X11: 2 | Y11: 2 | Z11: 6 | AA11: 2 | AB11: 2 | AC11: 2 | AD11: 2 | AE11: 2 | AF11: 2 | AG11: 6 | AH11: 2 | AI11: 2 | AJ11: 2 | AL11: 2 | AM11: 3 | AN11: 2 | AO11: 6 | AP11: 2 | BR11: =SUM(R11:BP11) -> 49 | BS11: =COUNTIF(F11:BP11,"A") -> 0
A12: 10 | B12: 2527497917 | C12: TILOK CHAND SHYOJI RAM | D12: Telescope Forklifter Operator | E12: EH | X12: 2 | Y12: 2 | Z12: 6 | AB12: 2 | AC12: 2 | AD12: 2 | AE12: 2 | AF12: 2 | AH12: 2 | AI12: 2 | AJ12: 2 | AL12: 2 | AM12: 3 | AN12: 2 | AP12: 2 | BR12: =SUM(R12:BP12) -> 35 | BS12: =COUNTIF(F12:BP12,"A") -> 0
A13: 11 | B13: 1018 | C13: SANA ULLAH HASHAM KHAN | D13: CONSTRUCTION WORKER | E13: EH | X13: 2 | Y13: A | Z13: 6 | AB13: 2 | AC13: 2 | AD13: 2 | AE13: 2 | AF13: 2 | AH13: A | AI13: 2 | AJ13: 2 | AL13: 2 | AM13: 2 | AN13: 2 | AO13: 6 | AP13: 2 | BR13: =SUM(R13:BP13) -> 36 | BS13: =COUNTIF(F13:BP13,"A") -> 2
A14: 12 | B14: 221 | C14: SARDAR ALI | D14: SURVEY DRIVER | E14: EH | X14: 4 | Y14: 4 | Z14: 8 | AA14: 4 | AB14: 4 | AC14: 4 | AD14: 4 | AE14: 4 | AF14: 4 | AG14: 8 | AH14: 4 | AI14: 4 | AJ14: 4 | AL14: 4 | AM14: 4 | AN14: S | AP14: S | BR14: =SUM(R14:BP14) -> 68 | BS14: =COUNTIF(F14:BP14,"A") -> 0 | BT14: Co. Driver/Emp. Service/Night Security P&D
A15: 13 | B15: 220 | C15: BARBAR HUSSAIN HAQ NAWAZ KHAN | D15: LOGISTICS OFFICER | E15: EH | X15: 2 | Y15: 2 | AA15: 2 | AB15: 2 | AC15: 2 | AD15: 2 | AE15: 2 | AF15: 2 | AH15: 2 | AI15: 2 | AJ15: 2 | AL15: 2 | AM15: 2 | AN15: 2 | AP15: 2 | BR15: =SUM(R15:BP15) -> 30 | BS15: =COUNTIF(F15:BP15,"A") -> 0
A16: 14 | B16: E00524 | C16: SOMAN MIAH MD ABDUL | D16: TEA BOY/OFFICE BOY | E16: EH | X16: 4 | Y16: 4 | Z16: 6 | AA16: 4 | AB16: 4 | AC16: 4 | AD16: 4 | AE16: 4 | AF16: 4 | AG16: 6 | AH16: 4 | AI16: 4 | AJ16: 4 | AL16: 4 | AM16: 4 | AN16: 4 | AO16: 6 | AP16: 4 | BR16: =SUM(R16:BP16) -> 78 | BS16: =COUNTIF(F16:BP16,"A") -> 0 | BT16: Site Teaboy / Office Boy / Friday Offices Cleaning
A17: 15 | B17: 2620914099 | C17: DHARMENDRA SAHANI | D17: CARPENTER | E17: EH | X17: 2 | Y17: 2 | Z17: 6 | AB17: 2 | AC17: 2 | AD17: 2 | AE17: 2 | AF17: 2 | AG17: 6 | AH17: 2 | AI17: 2 | AJ17: 2 | AL17: 2 | AM17: 2 | AN17: 2 | AO17: 6 | AP17: 2 | BR17: =SUM(R17:BP17) -> 46 | BS17: =COUNTIF(F17:BP17,"A") -> 0
A18: 16 | B18: 1 | C18: NAJRE ALAM SHEKH MOHAMMAD ARIF | D18: BRICK MASON | E18: EH | X18: 2 | Y18: 3 | Z18: 6 | AB18: 2 | AC18: 2 | AD18: 2 | AE18: 2 | AF18: 2 | AG18: 6 | AH18: 2 | AI18: 2 | AJ18: 2 | AL18: 2 | AM18: 3 | AN18: 2 | AO18: 6 | AP18: 2 | BR18: =SUM(R18:BP18) -> 48 | BS18: =COUNTIF(F18:BP18,"A") -> 0
A19: 17 | B19: 21 | C19: MOHAMMAD IRFAN KHAN | D19: CARPENTER | E19: EH | X19: V | Y19: V | AA19: V | AB19: V | AC19: V | AD19: V | AE19: V | AF19: V | AH19: V | AI19: V | AJ19: V | AL19: V | AM19: V | AN19: V | AP19: V | AQ19: V | AR19: V | AS19: V | AT19: V | AU19: V | AW19: V | AX19: V | AY19: V | AZ19: V | BA19: V | BB19: V | BD19: V | BE19: V | BR19: =SUM(R19:BP19) -> 0 | BS19: =COUNTIF(F19:BP19,"A") -> 0 | BT19: On Annual Vacation From (01.Aug.2026 to 22.Sep.2026)
A20: 18 | B20: 57 | C20: MUHAMMAD GHANI SHAH MUHAMMAD RAHIM SHAH | D20: MASON | E20: EH | X20: 2 | Y20: A | AB20: 2 | AC20: 2 | AD20: 2 | AE20: 2 | AF20: 2 | AH20: 2 | AI20: 2 | AJ20: 2 | AL20: 2 | AM20: 2 | AN20: 2 | AO20: 6 | AP20: 2 | BR20: =SUM(R20:BP20) -> 32 | BS20: =COUNTIF(F20:BP20,"A") -> 1
A21: 19 | B21: 62 | C21: ZAKIR KHAN HAZRAT GUL | D21: CARPENTER | E21: EH | X21: 2 | Y21: 2 | AB21: 2 | AC21: 2 | AD21: 2 | AE21: 2 | AF21: 2 | AH21: 2 | AI21: 2 | AJ21: 2 | AL21: 2 | AM21: 3 | AN21: 2 | AP21: 2 | BR21: =SUM(R21:BP21) -> 29 | BS21: =COUNTIF(F21:BP21,"A") -> 0
A22: 20 | B22: 65 | C22: MUHAMMAD QAMRAIZ SARFRAZ | D22: BLOCK MASON | E22: EH | X22: V | Y22: V | AA22: A | AB22: 2 | AC22: 2 | AD22: 2 | AE22: 2 | AF22: 2 | AH22: A | AI22: 2 | AJ22: 2 | AL22: 2 | AM22: 2 | AN22: 2 | AO22: 6 | AP22: 2 | BR22: =SUM(R22:BP22) -> 28 | BS22: =COUNTIF(F22:BP22,"A") -> 2 | BT22: On Annual Vacation From (28.June.2026 to 20.Aug.2026)
A23: 21 | B23: 69 | C23: SAYYAD ALI AMJAD ALI | D23: BLOCK MASON | E23: EH | X23: 3 | Y23: 3 | Z23: 6 | AB23: 4 | AC23: 3 | AD23: 3 | AE23: 4 | AF23: 3 | AG23: 6 | AH23: 3 | AI23: 3 | AJ23: 4 | AL23: 3 | AM23: 3 | AN23: 3 | AO23: 6 | AP23: 3 | BR23: =SUM(R23:BP23) -> 63 | BS23: =COUNTIF(F23:BP23,"A") -> 0 | BT23: Site Time Keeper, Logistic and Gate Pass & Multipl Tasks
A24: 22 | B24: 86 | C24: ZAHIR HAMEED SHAL HAMEED | D24: MASON | E24: EH | X24: 2 | Y24: 2 | Z24: 6 | AB24: 2 | AC24: 2 | AD24: 2 | AE24: 2 | AF24: 2 | AG24: 6 | AH24: 2 | AI24: 2 | AJ24: 2 | AL24: 2 | AM24: 2 | AN24: 2 | AO24: 6 | AP24: 2 | BF24: V | BG24: V | BH24: V | BI24: V | BJ24: V | BK24: V | BL24: V | BM24: V | BN24: V | BO24: V | BP24: V | BQ24: V | BR24: =SUM(R24:BP24) -> 46 | BS24: =COUNTIF(F24:BP24,"A") -> 0
A25: 23 | B25: 91 | C25: JALAL KHAN MUHAMMAD TAHIR | D25: CARPENTER | E25: EH | X25: 2 | Y25: 2 | AB25: A | AC25: 2 | AD25: 2 | AE25: 2 | AF25: 2 | AH25: 2 | AI25: A | AJ25: 2 | AL25: 2 | AM25: 3 | AN25: 2 | AO25: 6 | AP25: A | BR25: =SUM(R25:BP25) -> 29 | BS25: =COUNTIF(F25:BP25,"A") -> 3
A26: 24 | B26: 98 | C26: AQIB KHAN MUSLIM KHAN | D26: CARPENTER | E26: EH | X26: 4 | Y26: 4 | Z26: 12 | AA26: 4 | AB26: 6 | AC26: 4 | AD26: 6 | AE26: 4 | AF26: 4 | AH26: 6 | AI26: 4 | AJ26: 4 | AL26: 4 | AM26: 4 | AN26: 4 | AO26: 12 | AP26: 4 | BR26: =SUM(R26:BP26) -> 90 | BS26: =COUNTIF(F26:BP26,"A") -> 0 | BT26: On Duty Full Time : Store & Logistics Helper – Night Duty (Material Receiving)
A27: 25 | B27: 108 | C27: ARIF ABDUL WAHAB | D27: CARPENTER | E27: EH | X27: 4 | Y27: 4 | Z27: 12 | AA27: 4 | AB27: 4 | AC27: 4 | AD27: 4 | AE27: 4 | AF27: 4 | AG27: 12 | AH27: 3 | AI27: 3 | AJ27: 3 | AL27: 3 | AM27: 3 | AN27: 3 | AO27: 12 | AP27: 4 | BR27: =SUM(R27:BP27) -> 90 | BS27: =COUNTIF(F27:BP27,"A") -> 0 | BT27: Night Security
A28: 26 | B28: 113 | C28: MITHLESH KUMAR RAJNANDAN YADAV | D28: ELECTRICIAN | E28: EH | X28: 2 | Y28: 2 | Z28: 6 | AB28: 2 | AC28: 2 | AD28: 2 | AE28: 2 | AF28: 2 | AH28: 2 | AI28: 2 | AJ28: 2 | AL28: 2 | AM28: 2 | AN28: 2 | AO28: 6 | AP28: 2 | BR28: =SUM(R28:BP28) -> 40 | BS28: =COUNTIF(F28:BP28,"A") -> 0
A29: 27 | B29: 117 | C29: DEEN MOHAMMED JAFAR | D29: TILE MASON | E29: EH | X29: 2 | Y29: 2 | AB29: 2 | AC29: 2 | AD29: 2 | AE29: 2 | AF29: 2 | AH29: V | AI29: V | AJ29: A | AL29: 2 | AM29: 2 | AN29: 2 | AP29: 2 | BR29: =SUM(R29:BP29) -> 22 | BS29: =COUNTIF(F29:BP29,"A") -> 1 | BT29: 2 Days Internal Leave (29/30.Aug.2026)
A30: 28 | B30: 124 | C30: JAGDISH HEERA LAL | D30: PLASTER MASON | E30: EH | X30: 2 | Y30: 2 | AB30: A | AC30: 2 | AD30: 2 | AE30: 2 | AF30: 2 | AH30: 2 | AI30: 2 | AJ30: 2 | AL30: A | AM30: 3 | AN30: 2 | AP30: 2 | BR30: =SUM(R30:BP30) -> 25 | BS30: =COUNTIF(F30:BP30,"A") -> 2
A31: 29 | B31: 125 | C31: RINKU KUMAR BHANWAR LAL | D31: PLASTER MASON | E31: EH | X31: 4 | Y31: 4 | Z31: 12 | AA31: 4 | AB31: 4 | AC31: 4 | AD31: 4 | AE31: 4 | AF31: 4 | AG31: 12 | AH31: 3 | AI31: 3 | AJ31: 3 | AL31: 3 | AM31: 3 | AN31: 3 | AO31: 12 | AP31: 4 | BR31: =SUM(R31:BP31) -> 90 | BS31: =COUNTIF(F31:BP31,"A") -> 0 | BT31: Night Security
A32: 30 | B32: 128 | C32: MD MOKHTAR MD SALIM | D32: STEEL FIXER | E32: EH | X32: 2 | Y32: 2 | Z32: 6 | AB32: 2 | AC32: 2 | AD32: 2 | AE32: 2 | AF32: 2 | AG32: 6 | AH32: 2 | AI32: 2 | AJ32: 2 | AL32: 2 | AM32: 2 | AN32: 2 | AO32: 6 | AP32: 2 | BR32: =SUM(R32:BP32) -> 46 | BS32: =COUNTIF(F32:BP32,"A") -> 0
A33: 31 | B33: 133 | C33: MUHAMMAD HAFEEZ KHAN HASHIM KHAN | D33: PLUMBER | E33: EH | X33: 2 | Y33: 2 | Z33: 6 | AB33: 2 | AC33: 2 | AD33: 2 | AE33: 2 | AF33: 2 | AG33: 6 | AH33: 2 | AI33: 2 | AJ33: 2 | AL33: 2 | AM33: 2 | AN33: 2 | AO33: 6 | AP33: 2 | BR33: =SUM(R33:BP33) -> 46 | BS33: =COUNTIF(F33:BP33,"A") -> 0
A34: 32 | B34: 135 | C34: HABIB ULLAH KHAN NOOR ULLAH | D34: PLUMBER | E34: EH | X34: 2 | Y34: 2 | AB34: 2 | AC34: 2 | AD34: 2 | AE34: 2 | AF34: 2 | AH34: 2 | AI34: 2 | AJ34: 2 | AL34: 2 | AM34: 2 | AN34: A | AO34: 6 | AP34: 2 | BR34: =SUM(R34:BP34) -> 32 | BS34: =COUNTIF(F34:BP34,"A") -> 1
A35: 33 | B35: 141 | C35: SHAH HUSSAIN GHULAM DIN | D35: PLASTER MASON | E35: EH | X35: 4 | Y35: 6 | Z35: 12 | AA35: 4 | AB35: 4 | AC35: 4 | AD35: 4 | AE35: 4 | AF35: 4 | AG35: 12 | AH35: 6 | AI35: 4 | AJ35: 4 | AL35: 4 | AM35: 4 | AN35: 4 | AO35: 12 | AP35: 4 | BR35: =SUM(R35:BP35) -> 100 | BS35: =COUNTIF(F35:BP35,"A") -> 0 | BT35: On Duty Full Time - Store & Logistics Helper – Night Material Receiving
A36: 34 | B36: 153 | C36: MOSIM AHMAD - NIJAMUDDEEN | D36: TILE MASON | E36: EH | X36: 2 | Y36: 2 | Z36: 6 | AB36: 2 | AC36: 2 | AD36: 2 | AE36: 2 | AF36: 2 | AH36: 2 | AI36: 2 | AJ36: 2 | AL36: 2 | AM36: 2 | AN36: 2 | AO36: 6 | AP36: A | BR36: =SUM(R36:BP36) -> 38 | BS36: =COUNTIF(F36:BP36,"A") -> 1
A37: 35 | B37: 161 | C37: MUNEEB MUJAHID MUJAHID HUSSAIN | D37: BUS DRIVER | E37: EH | X37: 2 | Y37: 2 | Z37: 6 | AB37: 2 | AC37: 2 | AD37: 2 | AE37: 2 | AF37: 2 | AH37: 2 | AI37: 2 | AJ37: 2 | AL37: 2 | AM37: 2 | AN37: 5 | AO37: 6 | AP37: 2 | BR37: =SUM(R37:BP37) -> 43 | BS37: =COUNTIF(F37:BP37,"A") -> 0
A38: 36 | B38: 162 | C38: MUHAMMAD TOQEER MUHAMMAD LATIF | D38: BUS DRIVER | E38: EH | X38: 2 | Y38: 5 | Z38: 6 | AB38: 2 | AC38: 2 | AD38: 2 | AE38: 2 | AF38: 5 | AG38: 6 | AH38: 2 | AI38: 2 | AJ38: 2 | AL38: 2 | AM38: 3 | AN38: 2 | AP38: 2 | BR38: =SUM(R38:BP38) -> 47 | BS38: =COUNTIF(F38:BP38,"A") -> 0
A39: 37 | B39: 168 | C39: MUHAMMAD TOFIQUE MUHAMMAD SIDDIQUE | D39: BLOCK MASON | E39: EH | X39: 2 | Y39: A | AB39: 2 | AC39: 2 | AD39: 2 | AE39: 2 | AF39: 2 | AH39: 2 | AI39: 2 | AJ39: 2 | AL39: 2 | AM39: 2 | AN39: 2 | AO39: 6 | AP39: 2 | BR39: =SUM(R39:BP39) -> 32 | BS39: =COUNTIF(F39:BP39,"A") -> 1
A40: 38 | B40: 170 | C40: SAQIB REHMAN DLPAZEER AHMED | D40: PLUMBER | E40: EH | X40: 2 | Y40: A | AB40: 2 | AC40: 2 | AD40: 2 | AE40: 2 | AF40: A | AH40: A | AI40: 2 | AJ40: A | AL40: 2 | AM40: 2 | AN40: 2 | AO40: 6 | AP40: 2 | BR40: =SUM(R40:BP40) -> 26 | BS40: =COUNTIF(F40:BP40,"A") -> 4
...

Sheet MONTH SETTING
A1: MONTHS
A2: JANUARY | F2: FROM MONTH OF | G2: AUGUST
A3: FEBRUARY | F3: STARTING DATE | G3: =DATE(2026, MONTH(DATEVALUE("1"&G2)), DAY(DATEVALUE("1"&G2))) -> 46235
A4: MARCH | F4: Ending Date | G4: =EOMONTH(G3,0) -> 46265
A5: APRIL
A6: MAY | F6: TO | G6: SEPTEMBER
A7: JUNE | F7: STARTING DATE | G7: =DATE(2026, MONTH(DATEVALUE("1"&G6)), DAY(DATEVALUE("1"&G6))) -> 46266
A8: JULY | F8: Ending Date | G8: =EOMONTH(G7,0) -> 46295
A9: AUGUST
A10: SEPTEMBER
A11: OCTOBER
A12: NOVEMBER
A13: DECEMBER
H34: MOSTAFA MOHAMED MOSTAFA HAROUN

Sheet 2078939747
A1: {=MID(CELL("filename",A1),FIND("]",CELL("filename",A1))+1,255)} -> 2078939747
C2: طلب خارج الدوام Request for Over Time
Z3: Work description
C4: رقم الموظف | Employee No | D4: =A1 -> 2078939747 | I4: اسم الموظف | Employee Name | M4: {=_xlfn.LET( _xlpm.val, LOWER(TRIM(D4)), _xlfn.IFNA( _xlfn.XLOOKUP(_xlpm.val, LOWER(TRIM('EH Staff'!B:B)), 'EH Staff'!C:C, , 0, -1), _xlfn.XLOOKUP("*"&_xlpm.val&"*", LOWER(TRIM('EH Staff'!B:B)), 'EH Staff'!C:C, "", 2, -1) ) )} -> HAMADH ISMAIL HASSAN OLAYWA | X4: {=_xlfn.LET( _xlpm.val, LOWER(TRIM(D4)), _xlfn.IFNA( _xlfn.XLOOKUP(_xlpm.val, LOWER(TRIM('EH Staff'!B:B)), 'EH Staff'!D:D, , 0, -1), _xlfn.XLOOKUP("*"&_xlpm.val&"*", LOWER(TRIM('EH Staff'!B:B)), 'EH Staff'!D:D, "", 2, -1) ) )} -> SENIOR FOREMAN
C7: شهر | Month | D7: ='MONTH SETTING'!G2 -> AUGUST
C10: Date | تاريخ | D10: =TEXT('EH Staff'!F2,"DDD") -> Sat | E10: =TEXT('EH Staff'!G2,"DDD") -> Sun | F10: =TEXT('EH Staff'!H2,"DDD") -> Mon | G10: =TEXT('EH Staff'!I2,"DDD") -> Tue | H10: =TEXT('EH Staff'!J2,"DDD") -> Wed | I10: =TEXT('EH Staff'!K2,"DDD") -> Thu | J10: =TEXT('EH Staff'!L2,"DDD") -> Fri | K10: =TEXT('EH Staff'!M2,"DDD") -> Sat | ... AG10: =TEXT('EH Staff'!AI2,"DDD") -> Sun | AH10: =TEXT(AH11,"DDD") -> Mon
D11: ='MONTH SETTING'!$G$3 -> 46235 | E11: =IF(D11<'MONTH SETTING'!$G$4,D11+1,"") -> 46236 | F11: =IF(E11<'MONTH SETTING'!$G$4,E11+1,"") -> 46237 | G11: =IF(F11<'MONTH SETTING'!$G$4,F11+1,"") -> 46238 | H11: =IF(G11<'MONTH SETTING'!$G$4,G11+1,"") -> 46239 | I11: =IF(H11<'MONTH SETTING'!$G$4,H11+1,"") -> 46240 | J11: =IF(I11<'MONTH SETTING'!$G$4,I11+1,"") -> 46241 | K11: =IF(J11<'MONTH SETTING'!$G$4,J11+1,"") -> 46242 | L11: =IF(K11<'MONTH SETTING'!$G$4,K11+1,"") -> 46243 | ... AH11: =IF(AG11<'MONTH SETTING'!$G$4,AG11+1,"") -> 46265
C12: ساعات العمل الإضافي | Overtime Hours | V12: {=_xlfn.LET( _xlpm.key, LOWER(TRIM($D4)), _xlpm.rowData, _xlfn.IFNA( _xlfn.XLOOKUP(_xlpm.key, LOWER(TRIM('EH Staff'!$B$3:$B$716)), 'EH Staff'!$B$3:$BP$716, "", 0, -1), _xlfn.XLOOKUP("*"&_xlpm.key&"*", LOWER(TRIM('EH Staff'!$B$3:$B$716)), 'EH Staff'!$B$3:$BP$716, "", 2, -1) ), _xlpm.startCol, 23, INDEX(_xlpm.rowData, 1, _xlpm.startCol - 1 + COLUMNS($W4:W4)) )} -> 1 | W12: {=_xlfn.LET( _xlpm.key, LOWER(TRIM($D4)), _xlpm.rowData, _xlfn.IFNA( _xlfn.XLOOKUP(_xlpm.key, LOWER(TRIM('EH Staff'!$B$3:$B$716)), 'EH Staff'!$B$3:$BP$716, "", 0, -1), _xlfn.XLOOKUP("*"&_xlpm.key&"*", LOWER(TRIM('EH Staff'!$B$3:$B$716)), 'EH Staff'!$B$3:$BP$716, "", 2, -1) ), _xlpm.startCol, 23, INDEX(_xlpm.rowData, 1, _xlpm.startCol - 1 + COLUMNS($W4:X4)) )} -> 1 | X12: {=_xlfn.LET( _xlpm.key, LOWER(TRIM($D4)), _xlpm.rowData, _xlfn.IFNA( _xlfn.XLOOKUP(_xlpm.key, LOWER(TRIM('EH Staff'!$B$3:$B$716)), 'EH Staff'!$B$3:$BP$716, "", 0, -1), _xlfn.XLOOKUP("*"&_xlpm.key&"*", LOWER(TRIM('EH Staff'!$B$3:$B$716)), 'EH Staff'!$B$3:$BP$716, "", 2, -1) ), _xlpm.startCol, 23, INDEX(_xlpm.rowData, 1, _xlpm.startCol - 1 + COLUMNS($W4:Y4)) )} -> 0 | Y12: {=_xlfn.LET( _xlpm.key, LOWER(TRIM($D4)), _xlpm.rowData, _xlfn.IFNA( _xlfn.XLOOKUP(_xlpm.key, LOWER(TRIM('EH Staff'!$B$3:$B$716)), 'EH Staff'!$B$3:$BP$716, "", 0, -1), _xlfn.XLOOKUP("*"&_xlpm.key&"*", LOWER(TRIM('EH Staff'!$B$3:$B$716)), 'EH Staff'!$B$3:$BP$716, "", 2, -1) ), _xlpm.startCol, 23, INDEX(_xlpm.rowData, 1, _xlpm.startCol - 1 + COLUMNS($W4:Z4)) )} -> 1 | Z12: {=_xlfn.LET( _xlpm.key, LOWER(TRIM($D4)), _xlpm.rowData, _xlfn.IFNA( _xlfn.XLOOKUP(_xlpm.key, LOWER(TRIM('EH Staff'!$B$3:$B$716)), 'EH Staff'!$B$3:$BP$716, "", 0, -1), _xlfn.XLOOKUP("*"&_xlpm.key&"*", LOWER(TRIM('EH Staff'!$B$3:$B$716)), 'EH Staff'!$B$3:$BP$716, "", 2, -1) ), _xlpm.startCol, 23, INDEX(_xlpm.rowData, 1, _xlpm.startCol - 1 + COLUMNS($W4:AA4)) )} -> 1 | AA12: {=_xlfn.LET( _xlpm.key, LOWER(TRIM($D4)), _xlpm.rowData, _xlfn.IFNA( _xlfn.XLOOKUP(_xlpm.key, LOWER(TRIM('EH Staff'!$B$3:$B$716)), 'EH Staff'!$B$3:$BP$716, "", 0, -1), _xlfn.XLOOKUP("*"&_xlpm.key&"*", LOWER(TRIM('EH Staff'!$B$3:$B$716)), 'EH Staff'!$B$3:$BP$716, "", 2, -1) ), _xlpm.startCol, 23, INDEX(_xlpm.rowData, 1, _xlpm.startCol - 1 + COLUMNS($W4:AB4)) )} -> 1 | AB12: {=_xlfn.LET( _xlpm.key, LOWER(TRIM($D4)), _xlpm.rowData, _xlfn.IFNA( _xlfn.XLOOKUP(_xlpm.key, LOWER(TRIM('EH Staff'!$B$3:$B$716)), 'EH Staff'!$B$3:$BP$716, "", 0, -1), _xlfn.XLOOKUP("*"&_xlpm.key&"*", LOWER(TRIM('EH Staff'!$B$3:$B$716)), 'EH Staff'!$B$3:$BP$716, "", 2, -1) ), _xlpm.startCol, 23, INDEX(_xlpm.rowData, 1, _xlpm.startCol - 1 + COLUMNS($W4:AC4)) )} -> 1 | AC12: {=_xlfn.LET( _xlpm.key, LOWER(TRIM($D4)), _xlpm.rowData, _xlfn.IFNA( _xlfn.XLOOKUP(_xlpm.key, LOWER(TRIM('EH Staff'!$B$3:$B$716)), 'EH Staff'!$B$3:$BP$716, "", 0, -1), _xlfn.XLOOKUP("*"&_xlpm.key&"*", LOWER(TRIM('EH Staff'!$B$3:$B$716)), 'EH Staff'!$B$3:$BP$716, "", 2, -1) ), _xlpm.startCol, 23, INDEX(_xlpm.rowData, 1, _xlpm.startCol - 1 + COLUMNS($W4:AD4)) )} -> 1 | ... AH12: {=_xlfn.LET( _xlpm.key, LOWER(TRIM($D4)), _xlpm.rowData, _xlfn.IFNA( _xlfn.XLOOKUP(_xlpm.key, LOWER(TRIM('EH Staff'!$B$3:$B$716)), 'EH Staff'!$B$3:$BP$716, "", 0, -1), _xlfn.XLOOKUP("*"&_xlpm.key&"*", LOWER(TRIM('EH Staff'!$B$3:$B$716)), 'EH Staff'!$B$3:$BP$716, "", 2, -1) ), _xlpm.startCol, 23, INDEX(_xlpm.rowData, 1, _xlpm.startCol - 1 + COLUMNS($W4:AI4)) )} -> 1
D14: مجموع ساعات العمل الإضافي | Total Overtime Hours | G14: =SUM(D12:AH12) -> 11
AJ15: DROP DOWN | AK15: APRIL
AJ16: STARTING DATE | AK16: =DATEVALUE("1"&AK15) -> 45748
AJ17: Ending Date | AK17: =EOMONTH(AK16,0) -> 45777
C19: شهر | Month | D19: ='MONTH SETTING'!G6 -> SEPTEMBER | AJ19: DROP DOWN | AK19: MAY
AJ20: STARTING DATE | AK20: =DATEVALUE("1"&AK19) -> 45778
AJ21: Ending Date | AK21: =EOMONTH(AK20,0) -> 45808
C22: Date | تاريخ | D22: =TEXT('EH Staff'!AL2,"DDD") -> Tue | E22: =TEXT(E23,"DDD") -> Wed | F22: =TEXT(F23,"DDD") -> Thu | G22: =TEXT(G23,"DDD") -> Fri | H22: =TEXT(H23,"DDD") -> Sat | I22: =TEXT(I23,"DDD") -> Sun | J22: =TEXT(J23,"DDD") -> Mon | K22: =TEXT(K23,"DDD") -> Tue | L22: =TEXT(L23,"DDD") -> Wed | ... AH22: =TEXT(AH23,"DDD")
D23: ='MONTH SETTING'!$G$7 -> 46266 | E23: =IF(D23<'MONTH SETTING'!$G$8,D23+1,"") -> 46267 | F23: =IF(E23<'MONTH SETTING'!$G$8,E23+1,"") -> 46268 | G23: =IF(F23<'MONTH SETTING'!$G$8,F23+1,"") -> 46269 | H23: =IF(G23<'MONTH SETTING'!$G$8,G23+1,"") -> 46270 | I23: =IF(H23<'MONTH SETTING'!$G$8,H23+1,"") -> 46271 | J23: =IF(I23<'MONTH SETTING'!$G$8,I23+1,"") -> 46272 | K23: =IF(J23<'MONTH SETTING'!$G$8,J23+1,"") -> 46273 | L23: =IF(K23<'MONTH SETTING'!$G$8,K23+1,"") -> 46274 | ... AH23: =IF(AG23<'MONTH SETTING'!$G$8,AG23+1,"")
C24: ساعات العمل الإضافي | Overtime Hours | D24: {=_xlfn.LET( _xlpm.key, LOWER(TRIM($D4)), _xlpm.rowData, _xlfn.IFNA( _xlfn.XLOOKUP(_xlpm.key, LOWER(TRIM('EH Staff'!$B$3:$B$716)), 'EH Staff'!$B$3:$BP$716, "", 0, -1), _xlfn.XLOOKUP("*"&_xlpm.key&"*", LOWER(TRIM('EH Staff'!$B$3:$B$716)), 'EH Staff'!$B$3:$BP$716, "", 2, -1) ), _xlpm.startCol, 36, INDEX(_xlpm.rowData, 1, _xlpm.startCol - 1 + COLUMNS($AJ4:AK4)) )} -> 1 | E24: {=_xlfn.LET( _xlpm.key, LOWER(TRIM($D4)), _xlpm.rowData, _xlfn.IFNA( _xlfn.XLOOKUP(_xlpm.key, LOWER(TRIM('EH Staff'!$B$3:$B$716)), 'EH Staff'!$B$3:$BP$716, "", 0, -1), _xlfn.XLOOKUP("*"&_xlpm.key&"*", LOWER(TRIM('EH Staff'!$B$3:$B$716)), 'EH Staff'!$B$3:$BP$716, "", 2, -1) ), _xlpm.startCol, 36, INDEX(_xlpm.rowData, 1, _xlpm.startCol - 1 + COLUMNS($AJ4:AL4)) )} -> 1 | F24: {=_xlfn.LET( _xlpm.key, LOWER(TRIM($D4)), _xlpm.rowData, _xlfn.IFNA( _xlfn.XLOOKUP(_xlpm.key, LOWER(TRIM('EH Staff'!$B$3:$B$716)), 'EH Staff'!$B$3:$BP$716, "", 0, -1), _xlfn.XLOOKUP("*"&_xlpm.key&"*", LOWER(TRIM('EH Staff'!$B$3:$B$716)), 'EH Staff'!$B$3:$BP$716, "", 2, -1) ), _xlpm.startCol, 36, INDEX(_xlpm.rowData, 1, _xlpm.startCol - 1 + COLUMNS($AJ4:AM4)) )} -> 1 | G24: {=_xlfn.LET( _xlpm.key, LOWER(TRIM($D4)), _xlpm.rowData, _xlfn.IFNA( _xlfn.XLOOKUP(_xlpm.key, LOWER(TRIM('EH Staff'!$B$3:$B$716)), 'EH Staff'!$B$3:$BP$716, "", 0, -1), _xlfn.XLOOKUP("*"&_xlpm.key&"*", LOWER(TRIM('EH Staff'!$B$3:$B$716)), 'EH Staff'!$B$3:$BP$716, "", 2, -1) ), _xlpm.startCol, 36, INDEX(_xlpm.rowData, 1, _xlpm.startCol - 1 + COLUMNS($AJ4:AN4)) )} -> 0 | H24: {=_xlfn.LET( _xlpm.key, LOWER(TRIM($D4)), _xlpm.rowData, _xlfn.IFNA( _xlfn.XLOOKUP(_xlpm.key, LOWER(TRIM('EH Staff'!$B$3:$B$716)), 'EH Staff'!$B$3:$BP$716, "", 0, -1), _xlfn.XLOOKUP("*"&_xlpm.key&"*", LOWER(TRIM('EH Staff'!$B$3:$B$716)), 'EH Staff'!$B$3:$BP$716, "", 2, -1) ), _xlpm.startCol, 36, INDEX(_xlpm.rowData, 1, _xlpm.startCol - 1 + COLUMNS($AJ4:AO4)) )} -> 1 | I24: {=_xlfn.LET( _xlpm.key, LOWER(TRIM($D4)), _xlpm.rowData, _xlfn.IFNA( _xlfn.XLOOKUP(_xlpm.key, LOWER(TRIM('EH Staff'!$B$3:$B$716)), 'EH Staff'!$B$3:$BP$716, "", 0, -1), _xlfn.XLOOKUP("*"&_xlpm.key&"*", LOWER(TRIM('EH Staff'!$B$3:$B$716)), 'EH Staff'!$B$3:$BP$716, "", 2, -1) ), _xlpm.startCol, 36, INDEX(_xlpm.rowData, 1, _xlpm.startCol - 1 + COLUMNS($AJ4:AP4)) )} -> 0 | J24: {=_xlfn.LET( _xlpm.key, LOWER(TRIM($D4)), _xlpm.rowData, _xlfn.IFNA( _xlfn.XLOOKUP(_xlpm.key, LOWER(TRIM('EH Staff'!$B$3:$B$716)), 'EH Staff'!$B$3:$BP$716, "", 0, -1), _xlfn.XLOOKUP("*"&_xlpm.key&"*", LOWER(TRIM('EH Staff'!$B$3:$B$716)), 'EH Staff'!$B$3:$BP$716, "", 2, -1) ), _xlpm.startCol, 36, INDEX(_xlpm.rowData, 1, _xlpm.startCol - 1 + COLUMNS($AJ4:AQ4)) )} -> 0 | K24: {=_xlfn.LET( _xlpm.key, LOWER(TRIM($D4)), _xlpm.rowData, _xlfn.IFNA( _xlfn.XLOOKUP(_xlpm.key, LOWER(TRIM('EH Staff'!$B$3:$B$716)), 'EH Staff'!$B$3:$BP$716, "", 0, -1), _xlfn.XLOOKUP("*"&_xlpm.key&"*", LOWER(TRIM('EH Staff'!$B$3:$B$716)), 'EH Staff'!$B$3:$BP$716, "", 2, -1) ), _xlpm.startCol, 36, INDEX(_xlpm.rowData, 1, _xlpm.startCol - 1 + COLUMNS($AJ4:AR4)) )} -> 0 | ... W24: {=_xlfn.LET( _xlpm.key, LOWER(TRIM($D4)), _xlpm.rowData, _xlfn.IFNA( _xlfn.XLOOKUP(_xlpm.key, LOWER(TRIM('EH Staff'!$B$3:$B$716)), 'EH Staff'!$B$3:$BP$716, "", 0, -1), _xlfn.XLOOKUP("*"&_xlpm.key&"*", LOWER(TRIM('EH Staff'!$B$3:$B$716)), 'EH Staff'!$B$3:$BP$716, "", 2, -1) ), _xlpm.startCol, 36, INDEX(_xlpm.rowData, 1, _xlpm.startCol - 1 + COLUMNS($AJ4:BD4)) )} -> 0 | X24: {=_xlfn.LET( _xlpm.key, LOWER(TRIM($D4)), _xlpm.rowData, _xlfn.IFNA( _xlfn.XLOOKUP(_xlpm.key, LOWER(TRIM('EH Staff'!$B$3:$B$716)), 'EH Staff'!$B$3:$BP$716, "", 0, -1), _xlfn.XLOOKUP("*"&_xlpm.key&"*", LOWER(TRIM('EH Staff'!$B$3:$B$716)), 'EH Staff'!$B$3:$BP$716, "", 2, -1) ), _xlpm.startCol, 38, INDEX(_xlpm.rowData, 1, _xlpm.startCol - 1 + COLUMNS($AL4:BE4)) )} -> 0 | Y24: {=_xlfn.LET( _xlpm.key, LOWER(TRIM($D4)), _xlpm.rowData, _xlfn.IFNA( _xlfn.XLOOKUP(_xlpm.key, LOWER(TRIM('EH Staff'!$B$3:$B$716)), 'EH Staff'!$B$3:$BP$716, "", 0, -1), _xlfn.XLOOKUP("*"&_xlpm.key&"*", LOWER(TRIM('EH Staff'!$B$3:$B$716)), 'EH Staff'!$B$3:$BP$716, "", 2, -1) ), _xlpm.startCol, 38, INDEX(_xlpm.rowData, 1, _xlpm.startCol - 1 + COLUMNS($AL4:BF4)) )} -> 0 | Z24: {=_xlfn.LET( _xlpm.key, LOWER(TRIM($D4)), _xlpm.rowData, _xlfn.IFNA( _xlfn.XLOOKUP(_xlpm.key, LOWER(TRIM('EH Staff'!$B$3:$B$716)), 'EH Staff'!$B$3:$BP$716, "", 0, -1), _xlfn.XLOOKUP("*"&_xlpm.key&"*", LOWER(TRIM('EH Staff'!$B$3:$B$716)), 'EH Staff'!$B$3:$BP$716, "", 2, -1) ), _xlpm.startCol, 38, INDEX(_xlpm.rowData, 1, _xlpm.startCol - 1 + COLUMNS($AL4:BG4)) )} -> 0 | AA24: {=_xlfn.LET( _xlpm.key, LOWER(TRIM($D4)), _xlpm.rowData, _xlfn.IFNA( _xlfn.XLOOKUP(_xlpm.key, LOWER(TRIM('EH Staff'!$B$3:$B$716)), 'EH Staff'!$B$3:$BP$716, "", 0, -1), _xlfn.XLOOKUP("*"&_xlpm.key&"*", LOWER(TRIM('EH Staff'!$B$3:$B$716)), 'EH Staff'!$B$3:$BP$716, "", 2, -1) ), _xlpm.startCol, 38, INDEX(_xlpm.rowData, 1, _xlpm.startCol - 1 + COLUMNS($AL4:BH4)) )} -> 0 | AB24: {=_xlfn.LET( _xlpm.key, LOWER(TRIM($D4)), _xlpm.rowData, _xlfn.IFNA( _xlfn.XLOOKUP(_xlpm.key, LOWER(TRIM('EH Staff'!$B$3:$B$716)), 'EH Staff'!$B$3:$BP$716, "", 0, -1), _xlfn.XLOOKUP("*"&_xlpm.key&"*", LOWER(TRIM('EH Staff'!$B$3:$B$716)), 'EH Staff'!$B$3:$BP$716, "", 2, -1) ), _xlpm.startCol, 38, INDEX(_xlpm.rowData, 1, _xlpm.startCol - 1 + COLUMNS($AL4:BI4)) )} -> 0 | AC24: {=_xlfn.LET( _xlpm.key, LOWER(TRIM($D4)), _xlpm.rowData, _xlfn.IFNA( _xlfn.XLOOKUP(_xlpm.key, LOWER(TRIM('EH Staff'!$B$3:$B$716)), 'EH Staff'!$B$3:$BP$716, "", 0, -1), _xlfn.XLOOKUP("*"&_xlpm.key&"*", LOWER(TRIM('EH Staff'!$B$3:$B$716)), 'EH Staff'!$B$3:$BP$716, "", 2, -1) ), _xlpm.startCol, 38, INDEX(_xlpm.rowData, 1, _xlpm.startCol - 1 + COLUMNS($AL4:BJ4)) )} -> 0 | AD24: {=_xlfn.LET( _xlpm.key, LOWER(TRIM($D4)), _xlpm.rowData, _xlfn.IFNA( _xlfn.XLOOKUP(_xlpm.key, LOWER(TRIM('EH Staff'!$B$3:$B$716)), 'EH Staff'!$B$3:$BP$716, "", 0, -1), _xlfn.XLOOKUP("*"&_xlpm.key&"*", LOWER(TRIM('EH Staff'!$B$3:$B$716)), 'EH Staff'!$B$3:$BP$716, "", 2, -1) ), _xlpm.startCol, 38, INDEX(_xlpm.rowData, 1, _xlpm.startCol - 1 + COLUMNS($AL4:BK4)) )} -> 0 | AE24: {=_xlfn.LET( _xlpm.key, LOWER(TRIM($D4)), _xlpm.rowData, _xlfn.IFNA( _xlfn.XLOOKUP(_xlpm.key, LOWER(TRIM('EH Staff'!$B$3:$B$716)), 'EH Staff'!$B$3:$BP$716, "", 0, -1), _xlfn.XLOOKUP("*"&_xlpm.key&"*", LOWER(TRIM('EH Staff'!$B$3:$B$716)), 'EH Staff'!$B$3:$BP$716, "", 2, -1) ), _xlpm.startCol, 38, INDEX(_xlpm.rowData, 1, _xlpm.startCol - 1 + COLUMNS($AL4:BL4)) )} -> 0 | ... AH24: {=_xlfn.LET( _xlpm.key, LOWER(TRIM($D4)), _xlpm.rowData, _xlfn.IFNA( _xlfn.XLOOKUP(_xlpm.key, LOWER(TRIM('EH Staff'!$B$3:$B$716)), 'EH Staff'!$B$3:$BP$716, "", 0, -1), _xlfn.XLOOKUP("*"&_xlpm.key&"*", LOWER(TRIM('EH Staff'!$B$3:$B$716)), 'EH Staff'!$B$3:$BP$716, "", 2, -1) ), _xlpm.startCol, 38, INDEX(_xlpm.rowData, 1, _xlpm.startCol - 1 + COLUMNS($AL4:BO4)) )} -> 0
D26: مجموع ساعات العمل الإضافي | Total Overtime Hours | G26: =SUM(D24:AH24) -> 4 | W26: {=_xlfn.LET( _xlpm.key, LOWER(TRIM($D4)), _xlpm.rowData, _xlfn.IFNA( _xlfn.XLOOKUP(_xlpm.key, LOWER(TRIM('EH Staff'!$B$3:$B$716)), 'EH Staff'!$B$3:$BU$716, "", 0, -1), _xlfn.XLOOKUP("*"&_xlpm.key&"*", LOWER(TRIM('EH Staff'!$B$3:$B$716)), 'EH Staff'!$B$3:$BU$716, "", 2, -1) ), INDEX(_xlpm.rowData, 1, 71) )} -> 0
K28: مجموع ساعات العمل الإضافي | Total Overtime Hours | S28: =G14+G26 -> 15
D31: الموافقة | Approval
D32: Employee | H32: =M4 -> HAMADH ISMAIL HASSAN OLAYWA | V32: Date | تاريخ | W32: =NOW() -> 46270.368
D33: Line Manager | V33: Date | تاريخ | W33: =NOW() -> 46270.368
D34: Department Head | H34: MOSTAFA MOHAMED MOSTAFA HAROUN | V34: Date | تاريخ | W34: =NOW() -> 46270.368
D35: HR Manager | V35: Date | تاريخ
D36: MOSTAFA MOHAMED MOSTAFA HAROUN | V36: Date | تاريخ

Sheet 1401
A1: {=MID(CELL("filename",A1),FIND("]",CELL("filename",A1))+1,255)} -> 1401
C2: طلب خارج الدوام Request for Over Time
Z3: Work description
C4: رقم الموظف | Employee No | D4: =A1 -> 1401 | I4: اسم الموظف | Employee Name | M4: {=_xlfn.LET( _xlpm.val, LOWER(TRIM(D4)), _xlfn.IFNA( _xlfn.XLOOKUP(_xlpm.val, LOWER(TRIM('EH Staff'!B:B)), 'EH Staff'!C:C, , 0, -1), _xlfn.XLOOKUP("*"&_xlpm.val&"*", LOWER(TRIM('EH Staff'!B:B)), 'EH Staff'!C:C, "", 2, -1) ) )} -> SYED NISAR MEHDI | X4: {=_xlfn.LET( _xlpm.val, LOWER(TRIM(D4)), _xlfn.IFNA( _xlfn.XLOOKUP(_xlpm.val, LOWER(TRIM('EH Staff'!B:B)), 'EH Staff'!D:D, , 0, -1), _xlfn.XLOOKUP("*"&_xlpm.val&"*", LOWER(TRIM('EH Staff'!B:B)), 'EH Staff'!D:D, "", 2, -1) ) )} -> DC & ADMN.
C7: شهر | Month | D7: ='MONTH SETTING'!G2 -> AUGUST
C10: Date | تاريخ | D10: =TEXT('EH Staff'!F2,"DDD") -> Sat | E10: =TEXT('EH Staff'!G2,"DDD") -> Sun | F10: =TEXT('EH Staff'!H2,"DDD") -> Mon | G10: =TEXT('EH Staff'!I2,"DDD") -> Tue | H10: =TEXT('EH Staff'!J2,"DDD") -> Wed | I10: =TEXT('EH Staff'!K2,"DDD") -> Thu | J10: =TEXT('EH Staff'!L2,"DDD") -> Fri | K10: =TEXT('EH Staff'!M2,"DDD") -> Sat | ... AG10: =TEXT('EH Staff'!AI2,"DDD") -> Sun | AH10: =TEXT(AH11,"DDD") -> Mon
D11: ='MONTH SETTING'!$G$3 -> 46235 | E11: =IF(D11<'MONTH SETTING'!$G$4,D11+1,"") -> 46236 | F11: =IF(E11<'MONTH SETTING'!$G$4,E11+1,"") -> 46237 | G11: =IF(F11<'MONTH SETTING'!$G$4,F11+1,"") -> 46238 | H11: =IF(G11<'MONTH SETTING'!$G$4,G11+1,"") -> 46239 | I11: =IF(H11<'MONTH SETTING'!$G$4,H11+1,"") -> 46240 | J11: =IF(I11<'MONTH SETTING'!$G$4,I11+1,"") -> 46241 | K11: =IF(J11<'MONTH SETTING'!$G$4,J11+1,"") -> 46242 | L11: =IF(K11<'MONTH SETTING'!$G$4,K11+1,"") -> 46243 | ... AH11: =IF(AG11<'MONTH SETTING'!$G$4,AG11+1,"") -> 46265
C12: ساعات العمل الإضافي | Overtime Hours | V12: {=_xlfn.LET( _xlpm.key, LOWER(TRIM($D4)), _xlpm.rowData, _xlfn.IFNA( _xlfn.XLOOKUP(_xlpm.key, LOWER(TRIM('EH Staff'!$B$3:$B$716)), 'EH Staff'!$B$3:$BP$716, "", 0, -1), _xlfn.XLOOKUP("*"&_xlpm.key&"*", LOWER(TRIM('EH Staff'!$B$3:$B$716)), 'EH Staff'!$B$3:$BP$716, "", 2, -1) ), _xlpm.startCol, 23, INDEX(_xlpm.rowData, 1, _xlpm.startCol - 1 + COLUMNS($W4:W4)) )} -> 0 | W12: {=_xlfn.LET( _xlpm.key, LOWER(TRIM($D4)), _xlpm.rowData, _xlfn.IFNA( _xlfn.XLOOKUP(_xlpm.key, LOWER(TRIM('EH Staff'!$B$3:$B$716)), 'EH Staff'!$B$3:$BP$716, "", 0, -1), _xlfn.XLOOKUP("*"&_xlpm.key&"*", LOWER(TRIM('EH Staff'!$B$3:$B$716)), 'EH Staff'!$B$3:$BP$716, "", 2, -1) ), _xlpm.startCol, 23, INDEX(_xlpm.rowData, 1, _xlpm.startCol - 1 + COLUMNS($W4:X4)) )} -> 0 | X12: {=_xlfn.LET( _xlpm.key, LOWER(TRIM($D4)), _xlpm.rowData, _xlfn.IFNA( _xlfn.XLOOKUP(_xlpm.key, LOWER(TRIM('EH Staff'!$B$3:$B$716)), 'EH Staff'!$B$3:$BP$716, "", 0, -1), _xlfn.XLOOKUP("*"&_xlpm.key&"*", LOWER(TRIM('EH Staff'!$B$3:$B$716)), 'EH Staff'!$B$3:$BP$716, "", 2, -1) ), _xlpm.startCol, 23, INDEX(_xlpm.rowData, 1, _xlpm.startCol - 1 + COLUMNS($W4:Y4)) )} -> 0 | Y12: {=_xlfn.LET( _xlpm.key, LOWER(TRIM($D4)), _xlpm.rowData, _xlfn.IFNA( _xlfn.XLOOKUP(_xlpm.key, LOWER(TRIM('EH Staff'!$B$3:$B$716)), 'EH Staff'!$B$3:$BP$716, "", 0, -1), _xlfn.XLOOKUP("*"&_xlpm.key&"*", LOWER(TRIM('EH Staff'!$B$3:$B$716)), 'EH Staff'!$B$3:$BP$716, "", 2, -1) ), _xlpm.startCol, 23, INDEX(_xlpm.rowData, 1, _xlpm.startCol - 1 + COLUMNS($W4:Z4)) )} -> 0 | Z12: {=_xlfn.LET( _xlpm.key, LOWER(TRIM($D4)), _xlpm.rowData, _xlfn.IFNA( _xlfn.XLOOKUP(_xlpm.key, LOWER(TRIM('EH Staff'!$B$3:$B$716)), 'EH Staff'!$B$3:$BP$716, "", 0, -1), _xlfn.XLOOKUP("*"&_xlpm.key&"*", LOWER(TRIM('EH Staff'!$B$3:$B$716)), 'EH Staff'!$B$3:$BP$716, "", 2, -1) ), _xlpm.startCol, 23, INDEX(_xlpm.rowData, 1, _xlpm.startCol - 1 + COLUMNS($W4:AA4)) )} -> 0 | AA12: {=_xlfn.LET( _xlpm.key, LOWER(TRIM($D4)), _xlpm.rowData, _xlfn.IFNA( _xlfn.XLOOKUP(_xlpm.key, LOWER(TRIM('EH Staff'!$B$3:$B$716)), 'EH Staff'!$B$3:$BP$716, "", 0, -1), _xlfn.XLOOKUP("*"&_xlpm.key&"*", LOWER(TRIM('EH Staff'!$B$3:$B$716)), 'EH Staff'!$B$3:$BP$716, "", 2, -1) ), _xlpm.startCol, 23, INDEX(_xlpm.rowData, 1, _xlpm.startCol - 1 + COLUMNS($W4:AB4)) )} -> 0 | AB12: {=_xlfn.LET( _xlpm.key, LOWER(TRIM($D4)), _xlpm.rowData, _xlfn.IFNA( _xlfn.XLOOKUP(_xlpm.key, LOWER(TRIM('EH Staff'!$B$3:$B$716)), 'EH Staff'!$B$3:$BP$716, "", 0, -1), _xlfn.XLOOKUP("*"&_xlpm.key&"*", LOWER(TRIM('EH Staff'!$B$3:$B$716)), 'EH Staff'!$B$3:$BP$716, "", 2, -1) ), _xlpm.startCol, 23, INDEX(_xlpm.rowData, 1, _xlpm.startCol - 1 + COLUMNS($W4:AC4)) )} -> 0 | AC12: {=_xlfn.LET( _xlpm.key, LOWER(TRIM($D4)), _xlpm.rowData, _xlfn.IFNA( _xlfn.XLOOKUP(_xlpm.key, LOWER(TRIM('EH Staff'!$B$3:$B$716)), 'EH Staff'!$B$3:$BP$716, "", 0, -1), _xlfn.XLOOKUP("*"&_xlpm.key&"*", LOWER(TRIM('EH Staff'!$B$3:$B$716)), 'EH Staff'!$B$3:$BP$716, "", 2, -1) ), _xlpm.startCol, 23, INDEX(_xlpm.rowData, 1, _xlpm.startCol - 1 + COLUMNS($W4:AD4)) )} -> 0 | ... AH12: {=_xlfn.LET( _xlpm.key, LOWER(TRIM($D4)), _xlpm.rowData, _xlfn.IFNA( _xlfn.XLOOKUP(_xlpm.key, LOWER(TRIM('EH Staff'!$B$3:$B$716)), 'EH Staff'!$B$3:$BP$716, "", 0, -1), _xlfn.XLOOKUP("*"&_xlpm.key&"*", LOWER(TRIM('EH Staff'!$B$3:$B$716)), 'EH Staff'!$B$3:$BP$716, "", 2, -1) ), _xlpm.startCol, 23, INDEX(_xlpm.rowData, 1, _xlpm.startCol - 1 + COLUMNS($W4:AI4)) )} -> 0
D14: مجموع ساعات العمل الإضافي | Total Overtime Hours | G14: =SUM(D12:AH12) -> 0
AJ15: DROP DOWN | AK15: APRIL
AJ16: STARTING DATE | AK16: =DATEVALUE("1"&AK15) -> 45748
AJ17: Ending Date | AK17: =EOMONTH(AK16,0) -> 45777
C19: شهر | Month | D19: ='MONTH SETTING'!G6 -> SEPTEMBER | AJ19: DROP DOWN | AK19: MAY
AJ20: STARTING DATE | AK20: =DATEVALUE("1"&AK19) -> 45778
AJ21: Ending Date | AK21: =EOMONTH(AK20,0) -> 45808
C22: Date | تاريخ | D22: =TEXT('EH Staff'!AL2,"DDD") -> Tue | E22: =TEXT(E23,"DDD") -> Wed | F22: =TEXT(F23,"DDD") -> Thu | G22: =TEXT(G23,"DDD") -> Fri | H22: =TEXT(H23,"DDD") -> Sat | I22: =TEXT(I23,"DDD") -> Sun | J22: =TEXT(J23,"DDD") -> Mon | K22: =TEXT(K23,"DDD") -> Tue | L22: =TEXT(L23,"DDD") -> Wed | ... AH22: =TEXT(AH23,"DDD")
D23: ='MONTH SETTING'!$G$7 -> 46266 | E23: =IF(D23<'MONTH SETTING'!$G$8,D23+1,"") -> 46267 | F23: =IF(E23<'MONTH SETTING'!$G$8,E23+1,"") -> 46268 | G23: =IF(F23<'MONTH SETTING'!$G$8,F23+1,"") -> 46269 | H23: =IF(G23<'MONTH SETTING'!$G$8,G23+1,"") -> 46270 | I23: =IF(H23<'MONTH SETTING'!$G$8,H23+1,"") -> 46271 | J23: =IF(I23<'MONTH SETTING'!$G$8,I23+1,"") -> 46272 | K23: =IF(J23<'MONTH SETTING'!$G$8,J23+1,"") -> 46273 | L23: =IF(K23<'MONTH SETTING'!$G$8,K23+1,"") -> 46274 | ... AH23: =IF(AG23<'MONTH SETTING'!$G$8,AG23+1,"")
C24: ساعات العمل الإضافي | Overtime Hours | D24: {=_xlfn.LET( _xlpm.key, LOWER(TRIM($D4)), _xlpm.rowData, _xlfn.IFNA( _xlfn.XLOOKUP(_xlpm.key, LOWER(TRIM('EH Staff'!$B$3:$B$716)), 'EH Staff'!$B$3:$BP$716, "", 0, -1), _xlfn.XLOOKUP("*"&_xlpm.key&"*", LOWER(TRIM('EH Staff'!$B$3:$B$716)), 'EH Staff'!$B$3:$BP$716, "", 2, -1) ), _xlpm.startCol, 36, INDEX(_xlpm.rowData, 1, _xlpm.startCol - 1 + COLUMNS($AJ4:AK4)) )} -> 0 | E24: {=_xlfn.LET( _xlpm.key, LOWER(TRIM($D4)), _xlpm.rowData, _xlfn.IFNA( _xlfn.XLOOKUP(_xlpm.key, LOWER(TRIM('EH Staff'!$B$3:$B$716)), 'EH Staff'!$B$3:$BP$716, "", 0, -1), _xlfn.XLOOKUP("*"&_xlpm.key&"*", LOWER(TRIM('EH Staff'!$B$3:$B$716)), 'EH Staff'!$B$3:$BP$716, "", 2, -1) ), _xlpm.startCol, 36, INDEX(_xlpm.rowData, 1, _xlpm.startCol - 1 + COLUMNS($AJ4:AL4)) )} -> 0 | F24: {=_xlfn.LET( _xlpm.key, LOWER(TRIM($D4)), _xlpm.rowData, _xlfn.IFNA( _xlfn.XLOOKUP(_xlpm.key, LOWER(TRIM('EH Staff'!$B$3:$B$716)), 'EH Staff'!$B$3:$BP$716, "", 0, -1), _xlfn.XLOOKUP("*"&_xlpm.key&"*", LOWER(TRIM('EH Staff'!$B$3:$B$716)), 'EH Staff'!$B$3:$BP$716, "", 2, -1) ), _xlpm.startCol, 36, INDEX(_xlpm.rowData, 1, _xlpm.startCol - 1 + COLUMNS($AJ4:AM4)) )} -> 0 | G24: {=_xlfn.LET( _xlpm.key, LOWER(TRIM($D4)), _xlpm.rowData, _xlfn.IFNA( _xlfn.XLOOKUP(_xlpm.key, LOWER(TRIM('EH Staff'!$B$3:$B$716)), 'EH Staff'!$B$3:$BP$716, "", 0, -1), _xlfn.XLOOKUP("*"&_xlpm.key&"*", LOWER(TRIM('EH Staff'!$B$3:$B$716)), 'EH Staff'!$B$3:$BP$716, "", 2, -1) ), _xlpm.startCol, 36, INDEX(_xlpm.rowData, 1, _xlpm.startCol - 1 + COLUMNS($AJ4:AN4)) )} -> 0 | H24: {=_xlfn.LET( _xlpm.key, LOWER(TRIM($D4)), _xlpm.rowData, _xlfn.IFNA( _xlfn.XLOOKUP(_xlpm.key, LOWER(TRIM('EH Staff'!$B$3:$B$716)), 'EH Staff'!$B$3:$BP$716, "", 0, -1), _xlfn.XLOOKUP("*"&_xlpm.key&"*", LOWER(TRIM('EH Staff'!$B$3:$B$716)), 'EH Staff'!$B$3:$BP$716, "", 2, -1) ), _xlpm.startCol, 36, INDEX(_xlpm.rowData, 1, _xlpm.startCol - 1 + COLUMNS($AJ4:AO4)) )} -> 0 | I24: {=_xlfn.LET( _xlpm.key, LOWER(TRIM($D4)), _xlpm.rowData, _xlfn.IFNA( _xlfn.XLOOKUP(_xlpm.key, LOWER(TRIM('EH Staff'!$B$3:$B$716)), 'EH Staff'!$B$3:$BP$716, "", 0, -1), _xlfn.XLOOKUP("*"&_xlpm.key&"*", LOWER(TRIM('EH Staff'!$B$3:$B$716)), 'EH Staff'!$B$3:$BP$716, "", 2, -1) ), _xlpm.startCol, 36, INDEX(_xlpm.rowData, 1, _xlpm.startCol - 1 + COLUMNS($AJ4:AP4)) )} -> 0 | J24: {=_xlfn.LET( _xlpm.key, LOWER(TRIM($D4)), _xlpm.rowData, _xlfn.IFNA( _xlfn.XLOOKUP(_xlpm.key, LOWER(TRIM('EH Staff'!$B$3:$B$716)), 'EH Staff'!$B$3:$BP$716, "", 0, -1), _xlfn.XLOOKUP("*"&_xlpm.key&"*", LOWER(TRIM('EH Staff'!$B$3:$B$716)), 'EH Staff'!$B$3:$BP$716, "", 2, -1) ), _xlpm.startCol, 36, INDEX(_xlpm.rowData, 1, _xlpm.startCol - 1 + COLUMNS($AJ4:AQ4)) )} -> 0 | K24: {=_xlfn.LET( _xlpm.key, LOWER(TRIM($D4)), _xlpm.rowData, _xlfn.IFNA( _xlfn.XLOOKUP(_xlpm.key, LOWER(TRIM('EH Staff'!$B$3:$B$716)), 'EH Staff'!$B$3:$BP$716, "", 0, -1), _xlfn.XLOOKUP("*"&_xlpm.key&"*", LOWER(TRIM('EH Staff'!$B$3:$B$716)), 'EH Staff'!$B$3:$BP$716, "", 2, -1) ), _xlpm.startCol, 36, INDEX(_xlpm.rowData, 1, _xlpm.startCol - 1 + COLUMNS($AJ4:AR4)) )} -> 0 | ... W24: {=_xlfn.LET( _xlpm.key, LOWER(TRIM($D4)), _xlpm.rowData, _xlfn.IFNA( _xlfn.XLOOKUP(_xlpm.key, LOWER(TRIM('EH Staff'!$B$3:$B$716)), 'EH Staff'!$B$3:$BP$716, "", 0, -1), _xlfn.XLOOKUP("*"&_xlpm.key&"*", LOWER(TRIM('EH Staff'!$B$3:$B$716)), 'EH Staff'!$B$3:$BP$716, "", 2, -1) ), _xlpm.startCol, 36, INDEX(_xlpm.rowData, 1, _xlpm.startCol - 1 + COLUMNS($AJ4:BD4)) )} -> 0 | X24: {=_xlfn.LET( _xlpm.key, LOWER(TRIM($D4)), _xlpm.rowData, _xlfn.IFNA( _xlfn.XLOOKUP(_xlpm.key, LOWER(TRIM('EH Staff'!$B$3:$B$716)), 'EH Staff'!$B$3:$BP$716, "", 0, -1), _xlfn.XLOOKUP("*"&_xlpm.key&"*", LOWER(TRIM('EH Staff'!$B$3:$B$716)), 'EH Staff'!$B$3:$BP$716, "", 2, -1) ), _xlpm.startCol, 38, INDEX(_xlpm.rowData, 1, _xlpm.startCol - 1 + COLUMNS($AL4:BE4)) )} -> 0 | Y24: {=_xlfn.LET( _xlpm.key, LOWER(TRIM($D4)), _xlpm.rowData, _xlfn.IFNA( _xlfn.XLOOKUP(_xlpm.key, LOWER(TRIM('EH Staff'!$B$3:$B$716)), 'EH Staff'!$B$3:$BP$716, "", 0, -1), _xlfn.XLOOKUP("*"&_xlpm.key&"*", LOWER(TRIM('EH Staff'!$B$3:$B$716)), 'EH Staff'!$B$3:$BP$716, "", 2, -1) ), _xlpm.startCol, 38, INDEX(_xlpm.rowData, 1, _xlpm.startCol - 1 + COLUMNS($AL4:BF4)) )} -> 0 | Z24: {=_xlfn.LET( _xlpm.key, LOWER(TRIM($D4)), _xlpm.rowData, _xlfn.IFNA( _xlfn.XLOOKUP(_xlpm.key, LOWER(TRIM('EH Staff'!$B$3:$B$716)), 'EH Staff'!$B$3:$BP$716, "", 0, -1), _xlfn.XLOOKUP("*"&_xlpm.key&"*", LOWER(TRIM('EH Staff'!$B$3:$B$716)), 'EH Staff'!$B$3:$BP$716, "", 2, -1) ), _xlpm.startCol, 38, INDEX(_xlpm.rowData, 1, _xlpm.startCol - 1 + COLUMNS($AL4:BG4)) )} -> 0 | AA24: {=_xlfn.LET( _xlpm.key, LOWER(TRIM($D4)), _xlpm.rowData, _xlfn.IFNA( _xlfn.XLOOKUP(_xlpm.key, LOWER(TRIM('EH Staff'!$B$3:$B$716)), 'EH Staff'!$B$3:$BP$716, "", 0, -1), _xlfn.XLOOKUP("*"&_xlpm.key&"*", LOWER(TRIM('EH Staff'!$B$3:$B$716)), 'EH Staff'!$B$3:$BP$716, "", 2, -1) ), _xlpm.startCol, 38, INDEX(_xlpm.rowData, 1, _xlpm.startCol - 1 + COLUMNS($AL4:BH4)) )} -> 0 | AB24: {=_xlfn.LET( _xlpm.key, LOWER(TRIM($D4)), _xlpm.rowData, _xlfn.IFNA( _xlfn.XLOOKUP(_xlpm.key, LOWER(TRIM('EH Staff'!$B$3:$B$716)), 'EH Staff'!$B$3:$BP$716, "", 0, -1), _xlfn.XLOOKUP("*"&_xlpm.key&"*", LOWER(TRIM('EH Staff'!$B$3:$B$716)), 'EH Staff'!$B$3:$BP$716, "", 2, -1) ), _xlpm.startCol, 38, INDEX(_xlpm.rowData, 1, _xlpm.startCol - 1 + COLUMNS($AL4:BI4)) )} -> 0 | AC24: {=_xlfn.LET( _xlpm.key, LOWER(TRIM($D4)), _xlpm.rowData, _xlfn.IFNA( _xlfn.XLOOKUP(_xlpm.key, LOWER(TRIM('EH Staff'!$B$3:$B$716)), 'EH Staff'!$B$3:$BP$716, "", 0, -1), _xlfn.XLOOKUP("*"&_xlpm.key&"*", LOWER(TRIM('EH Staff'!$B$3:$B$716)), 'EH Staff'!$B$3:$BP$716, "", 2, -1) ), _xlpm.startCol, 38, INDEX(_xlpm.rowData, 1, _xlpm.startCol - 1 + COLUMNS($AL4:BJ4)) )} -> 0 | AD24: {=_xlfn.LET( _xlpm.key, LOWER(TRIM($D4)), _xlpm.rowData, _xlfn.IFNA( _xlfn.XLOOKUP(_xlpm.key, LOWER(TRIM('EH Staff'!$B$3:$B$716)), 'EH Staff'!$B$3:$BP$716, "", 0, -1), _xlfn.XLOOKUP("*"&_xlpm.key&"*", LOWER(TRIM('EH Staff'!$B$3:$B$716)), 'EH Staff'!$B$3:$BP$716, "", 2, -1) ), _xlpm.startCol, 38, INDEX(_xlpm.rowData, 1, _xlpm.startCol - 1 + COLUMNS($AL4:BK4)) )} -> 0 | AE24: {=_xlfn.LET( _xlpm.key, LOWER(TRIM($D4)), _xlpm.rowData, _xlfn.IFNA( _xlfn.XLOOKUP(_xlpm.key, LOWER(TRIM('EH Staff'!$B$3:$B$716)), 'EH Staff'!$B$3:$BP$716, "", 0, -1), _xlfn.XLOOKUP("*"&_xlpm.key&"*", LOWER(TRIM('EH Staff'!$B$3:$B$716)), 'EH Staff'!$B$3:$BP$716, "", 2, -1) ), _xlpm.startCol, 38, INDEX(_xlpm.rowData, 1, _xlpm.startCol - 1 + COLUMNS($AL4:BL4)) )} -> 0 | ... AH24: {=_xlfn.LET( _xlpm.key, LOWER(TRIM($D4)), _xlpm.rowData, _xlfn.IFNA( _xlfn.XLOOKUP(_xlpm.key, LOWER(TRIM('EH Staff'!$B$3:$B$716)), 'EH Staff'!$B$3:$BP$716, "", 0, -1), _xlfn.XLOOKUP("*"&_xlpm.key&"*", LOWER(TRIM('EH Staff'!$B$3:$B$716)), 'EH Staff'!$B$3:$BP$716, "", 2, -1) ), _xlpm.startCol, 38, INDEX(_xlpm.rowData, 1, _xlpm.startCol - 1 + COLUMNS($AL4:BO4)) )} -> 0
D26: مجموع ساعات العمل الإضافي | Total Overtime Hours | G26: =SUM(D24:AH24) -> 0 | W26: {=_xlfn.LET( _xlpm.key, LOWER(TRIM($D4)), _xlpm.rowData, _xlfn.IFNA( _xlfn.XLOOKUP(_xlpm.key, LOWER(TRIM('EH Staff'!$B$3:$B$716)), 'EH Staff'!$B$3:$BU$716, "", 0, -1), _xlfn.XLOOKUP("*"&_xlpm.key&"*", LOWER(TRIM('EH Staff'!$B$3:$B$716)), 'EH Staff'!$B$3:$BU$716, "", 2, -1) ), INDEX(_xlpm.rowData, 1, 71) )} -> Sick Leave
K28: مجموع ساعات العمل الإضافي | Total Overtime Hours | S28: =G14+G26 -> 0
D31: الموافقة | Approval
D32: Employee | H32: =M4 -> SYED NISAR MEHDI | V32: Date | تاريخ | W32: =NOW() -> 46270.368
D33: Line Manager | V33: Date | تاريخ | W33: =NOW() -> 46270.368
D34: Department Head | H34: MOSTAFA MOHAMED MOSTAFA HAROUN | V34: Date | تاريخ | W34: =NOW() -> 46270.368
D35: HR Manager | V35: Date | تاريخ
D36: MOSTAFA MOHAMED MOSTAFA HAROUN | V36: Date | تاريخ

Sheet 2512936473
A1: {=MID(CELL("filename",A1),FIND("]",CELL("filename",A1))+1,255)} -> 2512936473
C2: طلب خارج الدوام Request for Over Time
Z3: Work description
C4: رقم الموظف | Employee No | D4: =A1 -> 2512936473 | I4: اسم الموظف | Employee Name | M4: {=_xlfn.LET( _xlpm.val, LOWER(TRIM(D4)), _xlfn.IFNA( _xlfn.XLOOKUP(_xlpm.val, LOWER(TRIM('EH Staff'!B:B)), 'EH Staff'!C:C, , 0, -1), _xlfn.XLOOKUP("*"&_xlpm.val&"*", LOWER(TRIM('EH Staff'!B:B)), 'EH Staff'!C:C, "", 2, -1) ) )} -> MOHAMED ABDELNABI ABURIYA | X4: {=_xlfn.LET( _xlpm.val, LOWER(TRIM(D4)), _xlfn.IFNA( _xlfn.XLOOKUP(_xlpm.val, LOWER(TRIM('EH Staff'!B:B)), 'EH Staff'!D:D, , 0, -1), _xlfn.XLOOKUP("*"&_xlpm.val&"*", LOWER(TRIM('EH Staff'!B:B)), 'EH Staff'!D:D, "", 2, -1) ) )} -> FINISHING FOREMAN
C7: شهر | Month | D7: ='MONTH SETTING'!G2 -> AUGUST
C10: Date | تاريخ | D10: =TEXT('EH Staff'!F2,"DDD") -> Sat | E10: =TEXT('EH Staff'!G2,"DDD") -> Sun | F10: =TEXT('EH Staff'!H2,"DDD") -> Mon | G10: =TEXT('EH Staff'!I2,"DDD") -> Tue | H10: =TEXT('EH Staff'!J2,"DDD") -> Wed | I10: =TEXT('EH Staff'!K2,"DDD") -> Thu | J10: =TEXT('EH Staff'!L2,"DDD") -> Fri | K10: =TEXT('EH Staff'!M2,"DDD") -> Sat | ... AG10: =TEXT('EH Staff'!AI2,"DDD") -> Sun | AH10: =TEXT(AH11,"DDD") -> Mon
D11: ='MONTH SETTING'!$G$3 -> 46235 | E11: =IF(D11<'MONTH SETTING'!$G$4,D11+1,"") -> 46236 | F11: =IF(E11<'MONTH SETTING'!$G$4,E11+1,"") -> 46237 | G11: =IF(F11<'MONTH SETTING'!$G$4,F11+1,"") -> 46238 | H11: =IF(G11<'MONTH SETTING'!$G$4,G11+1,"") -> 46239 | I11: =IF(H11<'MONTH SETTING'!$G$4,H11+1,"") -> 46240 | J11: =IF(I11<'MONTH SETTING'!$G$4,I11+1,"") -> 46241 | K11: =IF(J11<'MONTH SETTING'!$G$4,J11+1,"") -> 46242 | L11: =IF(K11<'MONTH SETTING'!$G$4,K11+1,"") -> 46243 | ... AH11: =IF(AG11<'MONTH SETTING'!$G$4,AG11+1,"") -> 46265
C12: ساعات العمل الإضافي | Overtime Hours | V12: {=_xlfn.LET( _xlpm.key, LOWER(TRIM($D4)), _xlpm.rowData, _xlfn.IFNA( _xlfn.XLOOKUP(_xlpm.key, LOWER(TRIM('EH Staff'!$B$3:$B$716)), 'EH Staff'!$B$3:$BP$716, "", 0, -1), _xlfn.XLOOKUP("*"&_xlpm.key&"*", LOWER(TRIM('EH Staff'!$B$3:$B$716)), 'EH Staff'!$B$3:$BP$716, "", 2, -1) ), _xlpm.startCol, 23, INDEX(_xlpm.rowData, 1, _xlpm.startCol - 1 + COLUMNS($W4:W4)) )} -> V | W12: {=_xlfn.LET( _xlpm.key, LOWER(TRIM($D4)), _xlpm.rowData, _xlfn.IFNA( _xlfn.XLOOKUP(_xlpm.key, LOWER(TRIM('EH Staff'!$B$3:$B$716)), 'EH Staff'!$B$3:$BP$716, "", 0, -1), _xlfn.XLOOKUP("*"&_xlpm.key&"*", LOWER(TRIM('EH Staff'!$B$3:$B$716)), 'EH Staff'!$B$3:$BP$716, "", 2, -1) ), _xlpm.startCol, 23, INDEX(_xlpm.rowData, 1, _xlpm.startCol - 1 + COLUMNS($W4:X4)) )} -> V | X12: {=_xlfn.LET( _xlpm.key, LOWER(TRIM($D4)), _xlpm.rowData, _xlfn.IFNA( _xlfn.XLOOKUP(_xlpm.key, LOWER(TRIM('EH Staff'!$B$3:$B$716)), 'EH Staff'!$B$3:$BP$716, "", 0, -1), _xlfn.XLOOKUP("*"&_xlpm.key&"*", LOWER(TRIM('EH Staff'!$B$3:$B$716)), 'EH Staff'!$B$3:$BP$716, "", 2, -1) ), _xlpm.startCol, 23, INDEX(_xlpm.rowData, 1, _xlpm.startCol - 1 + COLUMNS($W4:Y4)) )} -> 0 | Y12: {=_xlfn.LET( _xlpm.key, LOWER(TRIM($D4)), _xlpm.rowData, _xlfn.IFNA( _xlfn.XLOOKUP(_xlpm.key, LOWER(TRIM('EH Staff'!$B$3:$B$716)), 'EH Staff'!$B$3:$BP$716, "", 0, -1), _xlfn.XLOOKUP("*"&_xlpm.key&"*", LOWER(TRIM('EH Staff'!$B$3:$B$716)), 'EH Staff'!$B$3:$BP$716, "", 2, -1) ), _xlpm.startCol, 23, INDEX(_xlpm.rowData, 1, _xlpm.startCol - 1 + COLUMNS($W4:Z4)) )} -> V | Z12: {=_xlfn.LET( _xlpm.key, LOWER(TRIM($D4)), _xlpm.rowData, _xlfn.IFNA( _xlfn.XLOOKUP(_xlpm.key, LOWER(TRIM('EH Staff'!$B$3:$B$716)), 'EH Staff'!$B$3:$BP$716, "", 0, -1), _xlfn.XLOOKUP("*"&_xlpm.key&"*", LOWER(TRIM('EH Staff'!$B$3:$B$716)), 'EH Staff'!$B$3:$BP$716, "", 2, -1) ), _xlpm.startCol, 23, INDEX(_xlpm.rowData, 1, _xlpm.startCol - 1 + COLUMNS($W4:AA4)) )} -> V | AA12: {=_xlfn.LET( _xlpm.key, LOWER(TRIM($D4)), _xlpm.rowData, _xlfn.IFNA( _xlfn.XLOOKUP(_xlpm.key, LOWER(TRIM('EH Staff'!$B$3:$B$716)), 'EH Staff'!$B$3:$BP$716, "", 0, -1), _xlfn.XLOOKUP("*"&_xlpm.key&"*", LOWER(TRIM('EH Staff'!$B$3:$B$716)), 'EH Staff'!$B$3:$BP$716, "", 2, -1) ), _xlpm.startCol, 23, INDEX(_xlpm.rowData, 1, _xlpm.startCol - 1 + COLUMNS($W4:AB4)) )} -> V | AB12: {=_xlfn.LET( _xlpm.key, LOWER(TRIM($D4)), _xlpm.rowData, _xlfn.IFNA( _xlfn.XLOOKUP(_xlpm.key, LOWER(TRIM('EH Staff'!$B$3:$B$716)), 'EH Staff'!$B$3:$BP$716, "", 0, -1), _xlfn.XLOOKUP("*"&_xlpm.key&"*", LOWER(TRIM('EH Staff'!$B$3:$B$716)), 'EH Staff'!$B$3:$BP$716, "", 2, -1) ), _xlpm.startCol, 23, INDEX(_xlpm.rowData, 1, _xlpm.startCol - 1 + COLUMNS($W4:AC4)) )} -> V | AC12: {=_xlfn.LET( _xlpm.key, LOWER(TRIM($D4)), _xlpm.rowData, _xlfn.IFNA( _xlfn.XLOOKUP(_xlpm.key, LOWER(TRIM('EH Staff'!$B$3:$B$716)), 'EH Staff'!$B$3:$BP$716, "", 0, -1), _xlfn.XLOOKUP("*"&_xlpm.key&"*", LOWER(TRIM('EH Staff'!$B$3:$B$716)), 'EH Staff'!$B$3:$BP$716, "", 2, -1) ), _xlpm.startCol, 23, INDEX(_xlpm.rowData, 1, _xlpm.startCol - 1 + COLUMNS($W4:AD4)) )} -> V | ... AH12: {=_xlfn.LET( _xlpm.key, LOWER(TRIM($D4)), _xlpm.rowData, _xlfn.IFNA( _xlfn.XLOOKUP(_xlpm.key, LOWER(TRIM('EH Staff'!$B$3:$B$716)), 'EH Staff'!$B$3:$BP$716, "", 0, -1), _xlfn.XLOOKUP("*"&_xlpm.key&"*", LOWER(TRIM('EH Staff'!$B$3:$B$716)), 'EH Staff'!$B$3:$BP$716, "", 2, -1) ), _xlpm.startCol, 23, INDEX(_xlpm.rowData, 1, _xlpm.startCol - 1 + COLUMNS($W4:AI4)) )} -> V
D14: مجموع ساعات العمل الإضافي | Total Overtime Hours | G14: =SUM(D12:AH12) -> 0
AJ15: DROP DOWN | AK15: APRIL
AJ16: STARTING DATE | AK16: =DATEVALUE("1"&AK15) -> 45748
AJ17: Ending Date | AK17: =EOMONTH(AK16,0) -> 45777
C19: شهر | Month | D19: ='MONTH SETTING'!G6 -> SEPTEMBER | AJ19: DROP DOWN | AK19: MAY
AJ20: STARTING DATE | AK20: =DATEVALUE("1"&AK19) -> 45778
AJ21: Ending Date | AK21: =EOMONTH(AK20,0) -> 45808
C22: Date | تاريخ | D22: =TEXT('EH Staff'!AL2,"DDD") -> Tue | E22: =TEXT(E23,"DDD") -> Wed | F22: =TEXT(F23,"DDD") -> Thu | G22: =TEXT(G23,"DDD") -> Fri | H22: =TEXT(H23,"DDD") -> Sat | I22: =TEXT(I23,"DDD") -> Sun | J22: =TEXT(J23,"DDD") -> Mon | K22: =TEXT(K23,"DDD") -> Tue | L22: =TEXT(L23,"DDD") -> Wed | ... AH22: =TEXT(AH23,"DDD")
D23: ='MONTH SETTING'!$G$7 -> 46266 | E23: =IF(D23<'MONTH SETTING'!$G$8,D23+1,"") -> 46267 | F23: =IF(E23<'MONTH SETTING'!$G$8,E23+1,"") -> 46268 | G23: =IF(F23<'MONTH SETTING'!$G$8,F23+1,"") -> 46269 | H23: =IF(G23<'MONTH SETTING'!$G$8,G23+1,"") -> 46270 | I23: =IF(H23<'MONTH SETTING'!$G$8,H23+1,"") -> 46271 | J23: =IF(I23<'MONTH SETTING'!$G$8,I23+1,"") -> 46272 | K23: =IF(J23<'MONTH SETTING'!$G$8,J23+1,"") -> 46273 | L23: =IF(K23<'MONTH SETTING'!$G$8,K23+1,"") -> 46274 | ... AH23: =IF(AG23<'MONTH SETTING'!$G$8,AG23+1,"")
C24: ساعات العمل الإضافي | Overtime Hours | D24: {=_xlfn.LET( _xlpm.key, LOWER(TRIM($D4)), _xlpm.rowData, _xlfn.IFNA( _xlfn.XLOOKUP(_xlpm.key, LOWER(TRIM('EH Staff'!$B$3:$B$716)), 'EH Staff'!$B$3:$BP$716, "", 0, -1), _xlfn.XLOOKUP("*"&_xlpm.key&"*", LOWER(TRIM('EH Staff'!$B$3:$B$716)), 'EH Staff'!$B$3:$BP$716, "", 2, -1) ), _xlpm.startCol, 36, INDEX(_xlpm.rowData, 1, _xlpm.startCol - 1 + COLUMNS($AJ4:AK4)) )} -> V | E24: {=_xlfn.LET( _xlpm.key, LOWER(TRIM($D4)), _xlpm.rowData, _xlfn.IFNA( _xlfn.XLOOKUP(_xlpm.key, LOWER(TRIM('EH Staff'!$B$3:$B$716)), 'EH Staff'!$B$3:$BP$716, "", 0, -1), _xlfn.XLOOKUP("*"&_xlpm.key&"*", LOWER(TRIM('EH Staff'!$B$3:$B$716)), 'EH Staff'!$B$3:$BP$716, "", 2, -1) ), _xlpm.startCol, 36, INDEX(_xlpm.rowData, 1, _xlpm.startCol - 1 + COLUMNS($AJ4:AL4)) )} -> V | F24: {=_xlfn.LET( _xlpm.key, LOWER(TRIM($D4)), _xlpm.rowData, _xlfn.IFNA( _xlfn.XLOOKUP(_xlpm.key, LOWER(TRIM('EH Staff'!$B$3:$B$716)), 'EH Staff'!$B$3:$BP$716, "", 0, -1), _xlfn.XLOOKUP("*"&_xlpm.key&"*", LOWER(TRIM('EH Staff'!$B$3:$B$716)), 'EH Staff'!$B$3:$BP$716, "", 2, -1) ), _xlpm.startCol, 36, INDEX(_xlpm.rowData, 1, _xlpm.startCol - 1 + COLUMNS($AJ4:AM4)) )} -> V | G24: {=_xlfn.LET( _xlpm.key, LOWER(TRIM($D4)), _xlpm.rowData, _xlfn.IFNA( _xlfn.XLOOKUP(_xlpm.key, LOWER(TRIM('EH Staff'!$B$3:$B$716)), 'EH Staff'!$B$3:$BP$716, "", 0, -1), _xlfn.XLOOKUP("*"&_xlpm.key&"*", LOWER(TRIM('EH Staff'!$B$3:$B$716)), 'EH Staff'!$B$3:$BP$716, "", 2, -1) ), _xlpm.startCol, 36, INDEX(_xlpm.rowData, 1, _xlpm.startCol - 1 + COLUMNS($AJ4:AN4)) )} -> 0 | H24: {=_xlfn.LET( _xlpm.key, LOWER(TRIM($D4)), _xlpm.rowData, _xlfn.IFNA( _xlfn.XLOOKUP(_xlpm.key, LOWER(TRIM('EH Staff'!$B$3:$B$716)), 'EH Staff'!$B$3:$BP$716, "", 0, -1), _xlfn.XLOOKUP("*"&_xlpm.key&"*", LOWER(TRIM('EH Staff'!$B$3:$B$716)), 'EH Staff'!$B$3:$BP$716, "", 2, -1) ), _xlpm.startCol, 36, INDEX(_xlpm.rowData, 1, _xlpm.startCol - 1 + COLUMNS($AJ4:AO4)) )} -> V | I24: {=_xlfn.LET( _xlpm.key, LOWER(TRIM($D4)), _xlpm.rowData, _xlfn.IFNA( _xlfn.XLOOKUP(_xlpm.key, LOWER(TRIM('EH Staff'!$B$3:$B$716)), 'EH Staff'!$B$3:$BP$716, "", 0, -1), _xlfn.XLOOKUP("*"&_xlpm.key&"*", LOWER(TRIM('EH Staff'!$B$3:$B$716)), 'EH Staff'!$B$3:$BP$716, "", 2, -1) ), _xlpm.startCol, 36, INDEX(_xlpm.rowData, 1, _xlpm.startCol - 1 + COLUMNS($AJ4:AP4)) )} -> V | J24: {=_xlfn.LET( _xlpm.key, LOWER(TRIM($D4)), _xlpm.rowData, _xlfn.IFNA( _xlfn.XLOOKUP(_xlpm.key, LOWER(TRIM('EH Staff'!$B$3:$B$716)), 'EH Staff'!$B$3:$BP$716, "", 0, -1), _xlfn.XLOOKUP("*"&_xlpm.key&"*", LOWER(TRIM('EH Staff'!$B$3:$B$716)), 'EH Staff'!$B$3:$BP$716, "", 2, -1) ), _xlpm.startCol, 36, INDEX(_xlpm.rowData, 1, _xlpm.startCol - 1 + COLUMNS($AJ4:AQ4)) )} -> V | K24: {=_xlfn.LET( _xlpm.key, LOWER(TRIM($D4)), _xlpm.rowData, _xlfn.IFNA( _xlfn.XLOOKUP(_xlpm.key, LOWER(TRIM('EH Staff'!$B$3:$B$716)), 'EH Staff'!$B$3:$BP$716, "", 0, -1), _xlfn.XLOOKUP("*"&_xlpm.key&"*", LOWER(TRIM('EH Staff'!$B$3:$B$716)), 'EH Staff'!$B$3:$BP$716, "", 2, -1) ), _xlpm.startCol, 36, INDEX(_xlpm.rowData, 1, _xlpm.startCol - 1 + COLUMNS($AJ4:AR4)) )} -> V | ... W24: {=_xlfn.LET( _xlpm.key, LOWER(TRIM($D4)), _xlpm.rowData, _xlfn.IFNA( _xlfn.XLOOKUP(_xlpm.key, LOWER(TRIM('EH Staff'!$B$3:$B$716)), 'EH Staff'!$B$3:$BP$716, "", 0, -1), _xlfn.XLOOKUP("*"&_xlpm.key&"*", LOWER(TRIM('EH Staff'!$B$3:$B$716)), 'EH Staff'!$B$3:$BP$716, "", 2, -1) ), _xlpm.startCol, 36, INDEX(_xlpm.rowData, 1, _xlpm.startCol - 1 + COLUMNS($AJ4:BD4)) )} -> 0 | X24: {=_xlfn.LET( _xlpm.key, LOWER(TRIM($D4)), _xlpm.rowData, _xlfn.IFNA( _xlfn.XLOOKUP(_xlpm.key, LOWER(TRIM('EH Staff'!$B$3:$B$716)), 'EH Staff'!$B$3:$BP$716, "", 0, -1), _xlfn.XLOOKUP("*"&_xlpm.key&"*", LOWER(TRIM('EH Staff'!$B$3:$B$716)), 'EH Staff'!$B$3:$BP$716, "", 2, -1) ), _xlpm.startCol, 38, INDEX(_xlpm.rowData, 1, _xlpm.startCol - 1 + COLUMNS($AL4:BE4)) )} -> 0 | Y24: {=_xlfn.LET( _xlpm.key, LOWER(TRIM($D4)), _xlpm.rowData, _xlfn.IFNA( _xlfn.XLOOKUP(_xlpm.key, LOWER(TRIM('EH Staff'!$B$3:$B$716)), 'EH Staff'!$B$3:$BP$716, "", 0, -1), _xlfn.XLOOKUP("*"&_xlpm.key&"*", LOWER(TRIM('EH Staff'!$B$3:$B$716)), 'EH Staff'!$B$3:$BP$716, "", 2, -1) ), _xlpm.startCol, 38, INDEX(_xlpm.rowData, 1, _xlpm.startCol - 1 + COLUMNS($AL4:BF4)) )} -> 0 | Z24: {=_xlfn.LET( _xlpm.key, LOWER(TRIM($D4)), _xlpm.rowData, _xlfn.IFNA( _xlfn.XLOOKUP(_xlpm.key, LOWER(TRIM('EH Staff'!$B$3:$B$716)), 'EH Staff'!$B$3:$BP$716, "", 0, -1), _xlfn.XLOOKUP("*"&_xlpm.key&"*", LOWER(TRIM('EH Staff'!$B$3:$B$716)), 'EH Staff'!$B$3:$BP$716, "", 2, -1) ), _xlpm.startCol, 38, INDEX(_xlpm.rowData, 1, _xlpm.startCol - 1 + COLUMNS($AL4:BG4)) )} -> 0 | AA24: {=_xlfn.LET( _xlpm.key, LOWER(TRIM($D4)), _xlpm.rowData, _xlfn.IFNA( _xlfn.XLOOKUP(_xlpm.key, LOWER(TRIM('EH Staff'!$B$3:$B$716)), 'EH Staff'!$B$3:$BP$716, "", 0, -1), _xlfn.XLOOKUP("*"&_xlpm.key&"*", LOWER(TRIM('EH Staff'!$B$3:$B$716)), 'EH Staff'!$B$3:$BP$716, "", 2, -1) ), _xlpm.startCol, 38, INDEX(_xlpm.rowData, 1, _xlpm.startCol - 1 + COLUMNS($AL4:BH4)) )} -> 0 | AB24: {=_xlfn.LET( _xlpm.key, LOWER(TRIM($D4)), _xlpm.rowData, _xlfn.IFNA( _xlfn.XLOOKUP(_xlpm.key, LOWER(TRIM('EH Staff'!$B$3:$B$716)), 'EH Staff'!$B$3:$BP$716, "", 0, -1), _xlfn.XLOOKUP("*"&_xlpm.key&"*", LOWER(TRIM('EH Staff'!$B$3:$B$716)), 'EH Staff'!$B$3:$BP$716, "", 2, -1) ), _xlpm.startCol, 38, INDEX(_xlpm.rowData, 1, _xlpm.startCol - 1 + COLUMNS($AL4:BI4)) )} -> 0 | AC24: {=_xlfn.LET( _xlpm.key, LOWER(TRIM($D4)), _xlpm.rowData, _xlfn.IFNA( _xlfn.XLOOKUP(_xlpm.key, LOWER(TRIM('EH Staff'!$B$3:$B$716)), 'EH Staff'!$B$3:$BP$716, "", 0, -1), _xlfn.XLOOKUP("*"&_xlpm.key&"*", LOWER(TRIM('EH Staff'!$B$3:$B$716)), 'EH Staff'!$B$3:$BP$716, "", 2, -1) ), _xlpm.startCol, 38, INDEX(_xlpm.rowData, 1, _xlpm.startCol - 1 + COLUMNS($AL4:BJ4)) )} -> 0 | AD24: {=_xlfn.LET( _xlpm.key, LOWER(TRIM($D4)), _xlpm.rowData, _xlfn.IFNA( _xlfn.XLOOKUP(_xlpm.key, LOWER(TRIM('EH Staff'!$B$3:$B$716)), 'EH Staff'!$B$3:$BP$716, "", 0, -1), _xlfn.XLOOKUP("*"&_xlpm.key&"*", LOWER(TRIM('EH Staff'!$B$3:$B$716)), 'EH Staff'!$B$3:$BP$716, "", 2, -1) ), _xlpm.startCol, 38, INDEX(_xlpm.rowData, 1, _xlpm.startCol - 1 + COLUMNS($AL4:BK4)) )} -> 0 | AE24: {=_xlfn.LET( _xlpm.key, LOWER(TRIM($D4)), _xlpm.rowData, _xlfn.IFNA( _xlfn.XLOOKUP(_xlpm.key, LOWER(TRIM('EH Staff'!$B$3:$B$716)), 'EH Staff'!$B$3:$BP$716, "", 0, -1), _xlfn.XLOOKUP("*"&_xlpm.key&"*", LOWER(TRIM('EH Staff'!$B$3:$B$716)), 'EH Staff'!$B$3:$BP$716, "", 2, -1) ), _xlpm.startCol, 38, INDEX(_xlpm.rowData, 1, _xlpm.startCol - 1 + COLUMNS($AL4:BL4)) )} -> 0 | ... AH24: {=_xlfn.LET( _xlpm.key, LOWER(TRIM($D4)), _xlpm.rowData, _xlfn.IFNA( _xlfn.XLOOKUP(_xlpm.key, LOWER(TRIM('EH Staff'!$B$3:$B$716)), 'EH Staff'!$B$3:$BP$716, "", 0, -1), _xlfn.XLOOKUP("*"&_xlpm.key&"*", LOWER(TRIM('EH Staff'!$B$3:$B$716)), 'EH Staff'!$B$3:$BP$716, "", 2, -1) ), _xlpm.startCol, 38, INDEX(_xlpm.rowData, 1, _xlpm.startCol - 1 + COLUMNS($AL4:BO4)) )} -> 0
D26: مجموع ساعات العمل الإضافي | Total Overtime Hours | G26: =SUM(D24:AH24) -> 0 | W26: {=_xlfn.LET( _xlpm.key, LOWER(TRIM($D4)), _xlpm.rowData, _xlfn.IFNA( _xlfn.XLOOKUP(_xlpm.key, LOWER(TRIM('EH Staff'!$B$3:$B$716)), 'EH Staff'!$B$3:$BU$716, "", 0, -1), _xlfn.XLOOKUP("*"&_xlpm.key&"*", LOWER(TRIM('EH Staff'!$B$3:$B$716)), 'EH Staff'!$B$3:$BU$716, "", 2, -1) ), INDEX(_xlpm.rowData, 1, 71) )} -> On Annual Vacation From (09.Aug.2026 to 8.Sep.2026)
K28: مجموع ساعات العمل الإضافي | Total Overtime Hours | S28: =G14+G26 -> 0
D31: الموافقة | Approval
D32: Employee | H32: =M4 -> MOHAMED ABDELNABI ABURIYA | V32: Date | تاريخ | W32: =NOW() -> 46270.368
D33: Line Manager | V33: Date | تاريخ | W33: =NOW() -> 46270.368
D34: Department Head | H34: MOSTAFA MOHAMED MOSTAFA HAROUN | V34: Date | تاريخ | W34: =NOW() -> 46270.368
D35: HR Manager | V35: Date | تاريخ
D36: MOSTAFA MOHAMED MOSTAFA HAROUN | V36: Date | تاريخ

Sheet 2377490566
A1: {=MID(CELL("filename",A1),FIND("]",CELL("filename",A1))+1,255)} -> 2377490566
C2: طلب خارج الدوام Request for Over Time
Z3: Work description
C4: رقم الموظف | Employee No | D4: =A1 -> 2377490566 | I4: اسم الموظف | Employee Name | M4: {=_xlfn.LET( _xlpm.val, LOWER(TRIM(D4)), _xlfn.IFNA( _xlfn.XLOOKUP(_xlpm.val, LOWER(TRIM('EH Staff'!B:B)), 'EH Staff'!C:C, , 0, -1), _xlfn.XLOOKUP("*"&_xlpm.val&"*", LOWER(TRIM('EH Staff'!B:B)), 'EH Staff'!C:C, "", 2, -1) ) )} -> AHMED SALAHELDIN IBRAHIM | X4: {=_xlfn.LET( _xlpm.val, LOWER(TRIM(D4)), _xlfn.IFNA( _xlfn.XLOOKUP(_xlpm.val, LOWER(TRIM('EH Staff'!B:B)), 'EH Staff'!D:D, , 0, -1), _xlfn.XLOOKUP("*"&_xlpm.val&"*", LOWER(TRIM('EH Staff'!B:B)), 'EH Staff'!D:D, "", 2, -1) ) )} -> SAFETY SUPERVISOR
C7: شهر | Month | D7: ='MONTH SETTING'!G2 -> AUGUST
C10: Date | تاريخ | D10: =TEXT('EH Staff'!F2,"DDD") -> Sat | E10: =TEXT('EH Staff'!G2,"DDD") -> Sun | F10: =TEXT('EH Staff'!H2,"DDD") -> Mon | G10: =TEXT('EH Staff'!I2,"DDD") -> Tue | H10: =TEXT('EH Staff'!J2,"DDD") -> Wed | I10: =TEXT('EH Staff'!K2,"DDD") -> Thu | J10: =TEXT('EH Staff'!L2,"DDD") -> Fri | K10: =TEXT('EH Staff'!M2,"DDD") -> Sat | ... AG10: =TEXT('EH Staff'!AI2,"DDD") -> Sun | AH10: =TEXT(AH11,"DDD") -> Mon
D11: ='MONTH SETTING'!$G$3 -> 46235 | E11: =IF(D11<'MONTH SETTING'!$G$4,D11+1,"") -> 46236 | F11: =IF(E11<'MONTH SETTING'!$G$4,E11+1,"") -> 46237 | G11: =IF(F11<'MONTH SETTING'!$G$4,F11+1,"") -> 46238 | H11: =IF(G11<'MONTH SETTING'!$G$4,G11+1,"") -> 46239 | I11: =IF(H11<'MONTH SETTING'!$G$4,H11+1,"") -> 46240 | J11: =IF(I11<'MONTH SETTING'!$G$4,I11+1,"") -> 46241 | K11: =IF(J11<'MONTH SETTING'!$G$4,J11+1,"") -> 46242 | L11: =IF(K11<'MONTH SETTING'!$G$4,K11+1,"") -> 46243 | ... AH11: =IF(AG11<'MONTH SETTING'!$G$4,AG11+1,"") -> 46265
