Workbook
Name MONTHS: #REF!

Sheet EH Staff
A1: HOMES Co. - MANPOWERS' OVERTIME (May. 15 '2026 -June. 20' 2026)
A2: SL # | B2: FILE # | C2: EMPLOYEE NAME | D2: POSITION | E2: COMPANY | F2: =TEXT(F3,"DDD") -> Fri | G2: =TEXT(G3,"DDD") -> Sat | H2: =TEXT(H3,"DDD") -> Sun | I2: =TEXT(I3,"DDD") -> Mon | J2: =TEXT(J3,"DDD") -> Tue | K2: =TEXT(K3,"DDD") -> Wed | L2: =TEXT(L3,"DDD") -> Thu | M2: =TEXT(M3,"DDD") -> Fri | ... AJ2: =TEXT(AJ3,"DDD") -> Sun | AL2: =TEXT(AL3,"DDD") -> Mon | AM2: =TEXT(AM3,"DDD") -> Tue | AN2: =TEXT(AN3,"DDD") -> Wed | AO2: =TEXT(AO3,"DDD") -> Thu | AP2: =TEXT(AP3,"DDD") -> Fri | AQ2: =TEXT(AQ3,"DDD") -> Sat | AR2: =TEXT(AR3,"DDD") -> Sun | AS2: =TEXT(AS3,"DDD") -> Mon | ... BP2: =TEXT(BP3,"DDD") | BR2: TOTAL | BS2: TOTAL | BT2: REMARKS
F3: ='MONTH SETTING'!G3 -> 46143 | G3: =IF(F3<'MONTH SETTING'!$G$4,F3+1,"") -> 46144 | H3: =IF(G3<'MONTH SETTING'!$G$4,G3+1,"") -> 46145 | I3: =IF(H3<'MONTH SETTING'!$G$4,H3+1,"") -> 46146 | J3: =IF(I3<'MONTH SETTING'!$G$4,I3+1,"") -> 46147 | K3: =IF(J3<'MONTH SETTING'!$G$4,J3+1,"") -> 46148 | L3: =IF(K3<'MONTH SETTING'!$G$4,K3+1,"") -> 46149 | M3: =IF(L3<'MONTH SETTING'!$G$4,L3+1,"") -> 46150 | N3: =IF(M3<'MONTH SETTING'!$G$4,M3+1,"") -> 46151 | ... AJ3: =IF(AI3<'MONTH SETTING'!$G$4,AI3+1,"") -> 46173 | AL3: ='MONTH SETTING'!$G$7 -> 46174 | AM3: =IF(AL3<'MONTH SETTING'!$G$8,AL3+1,"") -> 46175 | AN3: =IF(AM3<'MONTH SETTING'!$G$8,AM3+1,"") -> 46176 | AO3: =IF(AN3<'MONTH SETTING'!$G$8,AN3+1,"") -> 46177 | AP3: =IF(AO3<'MONTH SETTING'!$G$8,AO3+1,"") -> 46178 | AQ3: =IF(AP3<'MONTH SETTING'!$G$8,AP3+1,"") -> 46179 | AR3: =IF(AQ3<'MONTH SETTING'!$G$8,AQ3+1,"") -> 46180 | AS3: =IF(AR3<'MONTH SETTING'!$G$8,AR3+1,"") -> 46181 | AT3: =IF(AS3<'MONTH SETTING'!$G$8,AS3+1,"") -> 46182 | ... BP3: =IF(BO3<'MONTH SETTING'!$G$8,BO3+1,"") | BR3: OVERTIME | BS3: ABSENT DAYS
A4: 1 | B4: 2407930680 | C4: LAMBERT CAINGAT MOLINA | D4: ELEC. FOREMAN | E4: EH | U4: 2 | V4: 2 | W4: 2 | X4: 2 | Y4: 2 | Z4: S | AB4: 2 | AC4: 2 | AD4: 2 | AG4: 8 | AH4: 8 | AI4: 8 | AJ4: 4 | AL4: 4 | AM4: 4 | AN4: 4 | AO4: 4 | AP4: 6 | AQ4: 2 | AR4: 2 | AS4: 2 | AT4: 2 | AU4: 2 | AV4: 2 | AW4: 6 | AX4: 2 | AY4: 2 | AZ4: 2 | BA4: 2 | BB4: 2 | BC4: 2 | BR4: =SUM(R4:BP4) -> 96 | BS4: =COUNTIF(F4:BP4,"A") -> 0 | BT4: Worked during Eid Holiday
A5: 2 | B5: 220 | C5: BARBAR HUSSAIN HAQ NAWAZ KHAN | D5: LOGISTICS OFFICER | E5: EH | U5: 2 | V5: 2 | W5: 2 | X5: 2 | Y5: 2 | Z5: 2 | AB5: 2 | AC5: 2 | AD5: 2 | AJ5: 2 | AL5: 2 | AM5: 2 | AN5: 2 | AO5: 2 | AQ5: 2 | AR5: 2 | AS5: 2 | AT5: 2 | AU5: 2 | AV5: 2 | AX5: 2 | AY5: 2 | AZ5: 2 | BA5: 2 | BB5: 2 | BC5: 2 | BR5: =SUM(R5:BP5) -> 52 | BS5: =COUNTIF(F5:BP5,"A") -> 0
A6: 3 | B6: 2078939747 | C6: HAMADH ISMAIL HASSAN OLAYWA | D6: SENIOR FOREMAN | E6: - | U6: 1 | V6: S | X6: 1 | Y6: 1 | Z6: 1 | AB6: 1 | AC6: 1 | AD6: 1 | AJ6: 1 | AL6: 1 | AM6: 1 | AN6: 2 | AO6: 2 | AQ6: 1 | AR6: V | AS6: V | AT6: V | AU6: V | AV6: V | AX6: V | AY6: V | AZ6: 1 | BA6: 1 | BB6: 1 | BC6: 1 | BR6: =SUM(R6:BP6) -> 19 | BS6: =COUNTIF(F6:BP6,"A") -> 0 | BT6: Internal leave (7.June to 14.June)
A7: 4 | B7: 1401 | C7: SYED NISAR MEHDI | D7: DC & ADMN. | E7: EH | U7: 2 | V7: 4 | W7: 4 | X7: 4 | Y7: 4 | Z7: 2 | AB7: S | AC7: S | AD7: S | AJ7: V | AL7: V | AM7: V | AN7: V | AO7: V | AQ7: V | AR7: V | AS7: V | AT7: V | AU7: V | AV7: V | AX7: S | AY7: S | AZ7: S | BA7: S | BB7: S | BC7: S | BR7: =SUM(R7:BP7) -> 20 | BS7: =COUNTIF(F7:BP7,"A") -> 0 | BT7: Emergency Medical Leave (31.May-2026 to 11.June-2026)
A8: 5 | B8: 2588344990 | C8: IMRAN MUNIR | D8: SURVEYOR | E8: - | BR8: =SUM(R8:BP8) -> 0 | BS8: =COUNTIF(F8:BP8,"A") -> 0 | BT8: NO Overtime
A9: 6 | B9: 2377490566 | C9: AHMED SALAHELDIN IBRAHIM | D9: SAFETY SUPERVISOR | E9: - | U9: 2 | V9: 1 | W9: 1 | X9: 1 | Y9: 2 | Z9: 2 | AB9: 2 | AC9: 2 | AD9: 1 | AL9: 2 | AM9: 2 | AN9: 1 | AO9: 1 | AQ9: 1 | AR9: 2 | AS9: 2 | AT9: 2 | AU9: 2 | AV9: 2 | AX9: 2 | AY9: 2 | AZ9: 1 | BA9: 2 | BB9: 2 | BC9: 2 | BR9: =SUM(R9:BP9) -> 42 | BS9: =COUNTIF(F9:BP9,"A") -> 0
A10: 7 | B10: 778 | C10: SADDAM AJMAL MOHAMED | D10: STORE KEEPER | E10: EH | U10: 2 | V10: 2 | W10: 2 | X10: 2 | Y10: 2 | Z10: 2 | AB10: 2 | AC10: 2 | AD10: 2 | AJ10: 2 | AL10: 2 | AM10: 2 | AN10: 2 | AO10: 2 | AQ10: 2 | AR10: 2 | AS10: 2 | AT10: 2 | AU10: 2 | AV10: 2 | AX10: 2 | AY10: 2 | AZ10: 2 | BA10: 2 | BB10: 2 | BC10: 2 | BR10: =SUM(R10:BP10) -> 52 | BS10: =COUNTIF(F10:BP10,"A") -> 0
A11: 8 | B11: 2177529712 | C11: TAMAM ALI - MOSTAFA BARBAR | D11: CIVIL FOREMAN | E11: EH | U11: 2 | V11: 2 | W11: 2 | X11: 2 | Y11: 2 | Z11: 2 | AB11: 2 | AC11: 2 | AD11: 2 | AJ11: 2 | AL11: 2 | AN11: 2 | AO11: 2 | AQ11: 2 | AR11: 2 | AS11: 2 | AT11: 2 | AU11: 2 | AV11: 2 | AX11: TR | AY11: TR | AZ11: TR | BA11: TR | BB11: TR | BC11: TR | BR11: =SUM(R11:BP11) -> 38 | BS11: =COUNTIF(F11:BP11,"A") -> 0 | BT11: Transfer to Lissen View Project (13.June.2026)
A12: 9 | B12: 2412520922 | C12: RAMADAN RAMADAN ABDELHAMID ELGOHARY | D12: MECHANICAL FOREMAN | E12: - | U12: 1 | V12: 2 | W12: 2 | X12: 2 | Y12: 2 | Z12: 2 | AB12: 2 | AC12: 2 | AD12: 2 | AJ12: 2 | AL12: 2 | AM12: 2 | AN12: 2 | AO12: 2 | AQ12: 2 | AR12: S | AS12: 2 | AT12: 2 | AU12: 2 | AV12: 2 | AX12: 2 | AY12: 2 | AZ12: 2 | BA12: 2 | BB12: 2 | BC12: 2 | BR12: =SUM(R12:BP12) -> 49 | BS12: =COUNTIF(F12:BP12,"A") -> 0
A13: 10 | B13: 1018 | C13: SANA ULLAH HASHAM KHAN | D13: CONSTRUCTION WORKER | E13: EH | U13: A | V13: 2 | W13: 2 | X13: 2 | Y13: 2 | Z13: 2 | AB13: 2 | AC13: 2 | AD13: A | AJ13: A | AL13: 2 | AM13: 2 | AN13: 2 | AO13: A | AQ13: 2 | AR13: 2 | AS13: 2 | AT13: 2 | AU13: A | AV13: 2 | AX13: 2 | AY13: 2 | AZ13: 2 | BA13: 2 | BB13: A | BC13: 2 | BR13: =SUM(R13:BP13) -> 40 | BS13: =COUNTIF(F13:BP13,"A") -> 6
A14: 11 | B14: 221 | C14: SARDAR ALI | D14: SURVEY DRIVER | E14: EH | T14: 8 | U14: 4 | V14: 4 | W14: 4 | X14: 4 | Y14: 4 | Z14: 4 | AA14: 8 | AB14: 4 | AC14: 4 | AD14: 4 | AE14: 8 | AF14: 8 | AG14: 8 | AH14: 8 | AI14: 8 | AJ14: 4 | AL14: 4 | AM14: 4 | AN14: 4 | AO14: 4 | AP14: 8 | AQ14: 4 | AR14: 4 | AS14: 4 | AT14: 4 | AU14: 4 | AV14: 4 | AW14: 8 | AX14: 4 | AY14: 4 | AZ14: 4 | BA14: 4 | BB14: 4 | BC14: 4 | BR14: =SUM(R14:BP14) -> 176 | BS14: =COUNTIF(F14:BP14,"A") -> 0 | BT14: Co. Driver/Emp. Service/Night Security P&D
A15: 12 | B15: E00524 | C15: SOMAN MIAH MD ABDUL | D15: TEA BOY/OFFICE BOY | E15: EH | T15: 6 | U15: 3 | V15: 3 | W15: 3 | X15: 3 | Y15: 3 | Z15: 3 | AA15: 6 | AB15: 3 | AC15: 3 | AD15: 3 | AE15: 12 | AF15: 12 | AG15: 12 | AH15: 12 | AI15: 12 | AJ15: 3 | AL15: 3 | AM15: 3 | AN15: 3 | AO15: 3 | AP15: 6 | AQ15: 3 | AR15: 3 | AS15: 3 | AT15: 3 | AU15: 3 | AV15: 3 | AW15: 6 | AX15: 3 | AY15: 3 | AZ15: 3 | BA15: 3 | BB15: 3 | BC15: 3 | BR15: =SUM(R15:BP15) -> 162 | BS15: =COUNTIF(F15:BP15,"A") -> 0 | BT15: Site Teaboy / Office Boy / Friday Offices Cleaning
A16: 13 | B16: 1 | C16: NAJRE ALAM SHEKH MOHAMMAD ARIF | D16: BRICK MASON | E16: EH | U16: 2 | V16: 2 | W16: 2 | X16: 2 | Y16: 2 | Z16: 2 | AB16: 2 | AC16: 2 | AD16: 2 | AJ16: 2 | AL16: 2 | AM16: 2 | AN16: 2 | AO16: 2 | AQ16: 2 | AR16: 2 | AS16: 2 | AT16: 2 | AU16: 2 | AV16: 2 | AW16: 6 | AX16: 2 | AY16: 2 | AZ16: 2 | BA16: 2 | BB16: 2 | BC16: 2 | BR16: =SUM(R16:BP16) -> 58 | BS16: =COUNTIF(F16:BP16,"A") -> 0
A17: 14 | B17: 4 | C17: ARBAB AHMAD ISTIYAQ | D17: CARPENTER | E17: EH | U17: 2 | V17: 2 | W17: 2 | X17: 2 | Y17: 2 | Z17: 2 | AB17: 2 | AC17: 2 | AD17: 2 | AJ17: 2 | AL17: 2 | AM17: 2 | AN17: 2 | AO17: 2 | AQ17: 2 | AR17: 2 | AS17: 2 | AT17: TR | AU17: TR | AV17: TR | AX17: TR | AY17: TR | AZ17: TR | BA17: TR | BB17: TR | BC17: TR | BR17: =SUM(R17:BP17) -> 34 | BS17: =COUNTIF(F17:BP17,"A") -> 0 | BT17: Transfer to Lissen View Project (9.June.2026)
A18: 15 | B18: 9 | C18: JALALUDDIN ANSARI BABUJAN MIYAN | D18: PLUMBER | E18: EH | U18: 2 | V18: 2 | W18: 2 | X18: 2 | Y18: 2 | Z18: 2 | AB18: 2 | AC18: 2 | AD18: 2 | AJ18: 2 | AL18: 2 | AM18: 2 | AN18: TR | AO18: TR | AQ18: TR | AR18: TR | AS18: TR | AT18: TR | AU18: TR | AV18: TR | AX18: TR | AY18: TR | AZ18: TR | BA18: TR | BB18: TR | BC18: TR | BR18: =SUM(R18:BP18) -> 24 | BS18: =COUNTIF(F18:BP18,"A") -> 0 | BT18: Transfer to Lissen View Project (3.June.2026)
A19: 16 | B19: 21 | C19: MOHAMMAD IRFAN KHAN | D19: CARPENTER | E19: EH | U19: 2 | V19: 2 | W19: 2 | X19: 2 | Y19: 2 | Z19: 2 | AB19: 2 | AC19: 2 | AD19: 2 | AJ19: 2 | AL19: 2 | AM19: 2 | AN19: 2 | AO19: 2 | AQ19: 2 | AR19: 2 | AS19: 2 | AT19: 2 | AU19: 2 | AV19: 2 | AW19: 6 | AX19: 2 | AY19: 2 | AZ19: 2 | BA19: 2 | BB19: 2 | BC19: 2 | BR19: =SUM(R19:BP19) -> 58 | BS19: =COUNTIF(F19:BP19,"A") -> 0
A20: 17 | B20: 57 | C20: MUHAMMAD GHANI SHAH MUHAMMAD RAHIM SHAH | D20: MASON | E20: EH | U20: 2 | V20: 2 | W20: 2 | X20: 2 | Y20: 2 | Z20: 2 | AB20: 2 | AC20: 2 | AD20: 2 | AJ20: A | AL20: 2 | AM20: 2 | AN20: 2 | AO20: 2 | AQ20: 2 | AR20: 2 | AS20: 2 | AT20: 2 | AU20: 2 | AV20: 2 | AX20: 2 | AY20: 2 | AZ20: 2 | BA20: 2 | BB20: 2 | BC20: 2 | BR20: =SUM(R20:BP20) -> 50 | BS20: =COUNTIF(F20:BP20,"A") -> 1
A21: 18 | B21: 65 | C21: MUHAMMAD QAMRAIZ SARFRAZ | D21: BLOCK MASON | E21: EH | U21: 2 | V21: 2 | W21: 2 | X21: 2 | Y21: 2 | Z21: 2 | AB21: 2 | AC21: 2 | AD21: 2 | AJ21: 2 | AL21: 2 | AM21: 2 | AN21: 2 | AO21: 2 | AQ21: 2 | AR21: 2 | AS21: 2 | AT21: 2 | AU21: 2 | AV21: 2 | AX21: 2 | AY21: 2 | AZ21: 2 | BA21: 2 | BB21: 2 | BC21: 2 | BR21: =SUM(R21:BP21) -> 52 | BS21: =COUNTIF(F21:BP21,"A") -> 0
A22: 19 | B22: 69 | C22: SAYYAD ALI AMJAD ALI | D22: BLOCK MASON | E22: EH | T22: 6 | U22: 3 | V22: 3 | W22: 3 | X22: 3 | Y22: 3 | Z22: 3 | AA22: 6 | AB22: 3 | AC22: 3 | AD22: 3 | AE22: 12 | AF22: 12 | AG22: 12 | AH22: 12 | AI22: 12 | AJ22: 3 | AL22: 3 | AM22: 3 | AN22: 3 | AO22: 3 | AP22: 6 | AQ22: 3 | AR22: 3 | AS22: 3 | AT22: 3 | AU22: 3 | AV22: 3 | AW22: 6 | AX22: 3 | AY22: 3 | AZ22: 3 | BA22: 3 | BB22: 3 | BC22: 3 | BR22: =SUM(R22:BP22) -> 162 | BS22: =COUNTIF(F22:BP22,"A") -> 0 | BT22: Site Time Keeper, Logistic and Gate Pass & Multipl Tasks
A23: 20 | B23: 75 | C23: MUHAMMAD EHSAN SAFDAR SAFDAR HUSSAIN | D23: CARPENTER | E23: EH | U23: 2 | V23: A | W23: 2 | X23: 2 | Y23: 2 | Z23: 2 | AB23: 2 | AC23: 2 | AD23: 2 | AJ23: A | AL23: 2 | AM23: 2 | AN23: 2 | AO23: 2 | AQ23: 2 | AR23: 2 | AS23: 2 | AT23: TR | AU23: TR | AV23: TR | AX23: TR | AY23: TR | AZ23: TR | BA23: TR | BB23: TR | BC23: TR | BR23: =SUM(R23:BP23) -> 30 | BS23: =COUNTIF(F23:BP23,"A") -> 2 | BT23: Transfer to Lissen View Project (9.June.2026)
A24: 21 | B24: 86 | C24: ZAHIR HAMEED SHAL HAMEED | D24: MASON | E24: EH | U24: 2 | V24: 2 | W24: 2 | X24: 2 | Y24: 2 | Z24: 2 | AB24: 2 | AC24: 2 | AD24: 2 | AJ24: 2 | AL24: 2 | AM24: 2 | AN24: 2 | AO24: 2 | AQ24: 2 | AR24: 2 | AS24: 2 | AT24: 2 | AU24: 2 | AV24: 2 | AX24: 2 | AY24: 2 | AZ24: 2 | BA24: A | BB24: A | BC24: V | BR24: =SUM(R24:BP24) -> 46 | BS24: =COUNTIF(F24:BP24,"A") -> 2 | BT24: On Annual Vacation From (18.June.2026 to 10.Aug.2026)
A25: 22 | B25: 88 | C25: ARIF MAZHAR KHAN | D25: CARPENTER | E25: EH | U25: V | V25: V | W25: V | X25: V | Y25: V | Z25: V | AB25: V | AC25: V | AD25: V | AJ25: V | AL25: V | AM25: V | AN25: V | AO25: V | AQ25: V | AR25: V | AS25: V | AT25: V | AU25: V | AV25: V | AX25: A | AY25: 2 | AZ25: TR | BA25: TR | BB25: TR | BC25: TR | BR25: =SUM(R25:BP25) -> 2 | BS25: =COUNTIF(F25:BP25,"A") -> 1 | BT25: RED SEA to ROSHN / Resumed Duty After Vacation 11.June / Roshn to Lissen View 15.June.2026
A26: 23 | B26: 91 | C26: JALAL KHAN MUHAMMAD TAHIR | D26: CARPENTER | E26: EH | T26: 12 | U26: 4 | V26: 4 | W26: 4 | X26: 4 | Y26: 4 | Z26: 4 | AA26: 12 | AB26: 4 | AC26: 4 | AD26: 4 | AE26: 12 | AF26: 12 | AG26: 12 | AH26: 12 | AI26: 12 | AJ26: 4 | AL26: 4 | AM26: 4 | AN26: 4 | AO26: 4 | AP26: 12 | AQ26: 4 | AR26: 4 | AS26: 4 | AT26: 4 | AU26: 4 | AV26: 4 | AX26: 2 | AY26: 2 | AZ26: 2 | BA26: 2 | BB26: 2 | BC26: 2 | BR26: =SUM(R26:BP26) -> 188 | BS26: =COUNTIF(F26:BP26,"A") -> 0 | BT26: Night Security
A27: 24 | B27: 98 | C27: AQIB KHAN MUSLIM KHAN | D27: CARPENTER | E27: EH | T27: 12 | U27: 4 | V27: 4 | W27: 4 | X27: 4 | Y27: 4 | Z27: 4 | AA27: 12 | AB27: 4 | AC27: 4 | AD27: 4 | AE27: 12 | AF27: 12 | AG27: 12 | AH27: 12 | AI27: 12 | AJ27: 4 | AL27: 4 | AM27: 4 | AN27: 4 | AO27: 4 | AP27: 12 | AQ27: 4 | AR27: 4 | AS27: 4 | AT27: 4 | AU27: 4 | AV27: 4 | AW27: 12 | AX27: 4 | AY27: 4 | AZ27: 4 | BA27: 4 | BB27: 4 | BC27: 4 | BR27: =SUM(R27:BP27) -> 212 | BS27: =COUNTIF(F27:BP27,"A") -> 0 | BT27: On Duty Full Time : Store & Logistics Helper – Night Duty (Material Receiving)
A28: 25 | B28: 108 | C28: ARIF ABDUL WAHAB | D28: CARPENTER | E28: EH | T28: 12 | U28: 4 | V28: 4 | W28: 4 | X28: 4 | Y28: 4 | Z28: 4 | AA28: 12 | AB28: 4 | AC28: 4 | AD28: 4 | AE28: 12 | AF28: 12 | AG28: 12 | AH28: 12 | AI28: 12 | AJ28: 4 | AL28: 4 | AM28: 4 | AN28: 4 | AO28: 4 | AP28: 12 | AQ28: 4 | AR28: 4 | AS28: 4 | AT28: 4 | AU28: 4 | AV28: 4 | AW28: 12 | AX28: 4 | AY28: 4 | AZ28: 4 | BA28: 4 | BB28: 4 | BC28: 4 | BR28: =SUM(R28:BP28) -> 212 | BS28: =COUNTIF(F28:BP28,"A") -> 0 | BT28: Night Security
A29: 26 | B29: 113 | C29: MITHLESH KUMAR RAJNANDAN YADAV | D29: ELECTRICIAN | E29: EH | U29: 2 | V29: 2 | W29: 2 | X29: 2 | Y29: 2 | Z29: 2 | AB29: 2 | AC29: 2 | AD29: 2 | AJ29: 3 | AL29: 3 | AM29: 3 | AN29: 3 | AO29: 3 | AP29: 6 | AQ29: 2 | AR29: 2 | AS29: 2 | AT29: 2 | AU29: 2 | AV29: 2 | AW29: 6 | AX29: 2 | AY29: 2 | AZ29: 2 | BA29: 2 | BB29: 2 | BC29: 2 | BR29: =SUM(R29:BP29) -> 69 | BS29: =COUNTIF(F29:BP29,"A") -> 0
A30: 27 | B30: 117 | C30: DEEN MOHAMMED JAFAR | D30: TILE MASON | E30: EH | U30: 2 | V30: 2 | W30: 2 | X30: 2 | Y30: A | Z30: 2 | AB30: 2 | AC30: 2 | AD30: 2 | AJ30: A | AL30: 2 | AM30: 2 | AN30: A | AO30: 2 | AQ30: S | AR30: S | AS30: 2 | AT30: 2 | AU30: 2 | AV30: 2 | AX30: 2 | AY30: 2 | AZ30: A | BA30: 2 | BB30: 2 | BC30: 2 | BR30: =SUM(R30:BP30) -> 40 | BS30: =COUNTIF(F30:BP30,"A") -> 4 | BT30: RED SEA to ROSHN on May.16
A31: 28 | B31: 124 | C31: JAGDISH HEERA LAL | D31: PLASTER MASON | E31: EH | U31: V | V31: V | W31: V | X31: V | Y31: V | Z31: V | AB31: V | AC31: V | AD31: V | AJ31: V | AL31: V | AM31: V | AN31: V | AO31: V | AQ31: V | AR31: V | AS31: V | AT31: V | AU31: 2 | AV31: 2 | AX31: 2 | AY31: 2 | AZ31: A | BA31: 2 | BB31: 2 | BC31: 2 | BR31: =SUM(R31:BP31) -> 14 | BS31: =COUNTIF(F31:BP31,"A") -> 1 | BT31: Resumed Duty After Annual Vacation (10.June.2026)
A32: 29 | B32: 125 | C32: RINKU KUMAR BHANWAR LAL | D32: PLASTER MASON | E32: EH | T32: 12 | U32: 4 | V32: 4 | W32: 4 | X32: 4 | Y32: 4 | Z32: 4 | AA32: 12 | AB32: 4 | AC32: 4 | AD32: 4 | AE32: 12 | AF32: 12 | AG32: 12 | AH32: 12 | AI32: 12 | AJ32: 4 | AL32: 4 | AM32: 4 | AN32: 4 | AO32: 4 | AP32: 12 | AQ32: 4 | AR32: 4 | AS32: 4 | AT32: 4 | AU32: 4 | AV32: 4 | AW32: 12 | AX32: 4 | AY32: 4 | AZ32: 4 | BA32: 4 | BB32: 4 | BC32: 4 | BR32: =SUM(R32:BP32) -> 212 | BS32: =COUNTIF(F32:BP32,"A") -> 0 | BT32: Night Security
A33: 30 | B33: 133 | C33: MUHAMMAD HAFEEZ KHAN HASHIM KHAN | D33: PLUMBER | E33: EH | U33: 2 | V33: 2 | W33: 2 | X33: 2 | Y33: 2 | Z33: 2 | AB33: 2 | AC33: 2 | AD33: 2 | AJ33: 3 | AL33: 3 | AM33: 3 | AN33: 3 | AO33: 3 | AP33: 6 | AQ33: 2 | AR33: 2 | AS33: 2 | AT33: 2 | AU33: 2 | AV33: 2 | AW33: 6 | AX33: 2 | AY33: 2 | AZ33: 2 | BA33: 2 | BB33: 2 | BC33: 2 | BR33: =SUM(R33:BP33) -> 69 | BS33: =COUNTIF(F33:BP33,"A") -> 0
A34: 31 | B34: 135 | C34: HABIB ULLAH KHAN NOOR ULLAH | D34: PLUMBER | E34: EH | U34: 2 | V34: 2 | W34: 2 | X34: 2 | Y34: 2 | Z34: 2 | AB34: 2 | AC34: 2 | AD34: 2 | AJ34: 2 | AL34: 2 | AM34: 2 | AN34: 2 | AO34: 2 | AQ34: 2 | AR34: 2 | AS34: 2 | AT34: 2 | AU34: 2 | AV34: 2 | AX34: 2 | AY34: 2 | AZ34: 2 | BA34: 2 | BB34: 2 | BC34: 2 | BR34: =SUM(R34:BP34) -> 52 | BS34: =COUNTIF(F34:BP34,"A") -> 0
A35: 32 | B35: 141 | C35: SHAH HUSSAIN GHULAM DIN | D35: PLASTER MASON | E35: EH | T35: 12 | U35: 4 | V35: 4 | W35: 4 | X35: 4 | Y35: 4 | Z35: 4 | AA35: 12 | AB35: 4 | AC35: 4 | AD35: 4 | AE35: 12 | AF35: 12 | AG35: 12 | AH35: 12 | AI35: 12 | AJ35: 4 | AL35: 4 | AM35: 4 | AN35: 4 | AO35: 4 | AP35: 12 | AQ35: 4 | AR35: 4 | AS35: 4 | AT35: 4 | AU35: 4 | AV35: 4 | AW35: 12 | AX35: 4 | AY35: 4 | AZ35: 4 | BA35: 4 | BB35: 4 | BC35: 4 | BR35: =SUM(R35:BP35) -> 212 | BS35: =COUNTIF(F35:BP35,"A") -> 0 | BT35: On Duty Full Time - Store & Logistics Helper – Night Material Receiving
A36: 33 | B36: 142 | C36: MUHAMMAD IBRAHIM YAQOOB KHAN | D36: CARPENTER | E36: EH | T36: 12 | U36: 4 | V36: 4 | W36: 4 | X36: 4 | Y36: 4 | Z36: 4 | AA36: 12 | AB36: 4 | AC36: 4 | AD36: 4 | AE36: 12 | AF36: 12 | AG36: 12 | AH36: 12 | AI36: 12 | AJ36: 4 | AL36: 4 | AM36: 4 | AN36: 4 | AO36: 4 | AP36: 12 | AQ36: 4 | AR36: 4 | AS36: 4 | AT36: 4 | AU36: 4 | AV36: 4 | AW36: 12 | AX36: 4 | AY36: 4 | AZ36: 4 | BA36: 4 | BB36: 4 | BC36: 4 | BR36: =SUM(R36:BP36) -> 212 | BS36: =COUNTIF(F36:BP36,"A") -> 0 | BT36: Duty Full Time - Store & Logistic Helper, Night Duty For Material Receiving
A37: 34 | B37: 153 | C37: MOSIM AHMAD - NIJAMUDDEEN | D37: TILE MASON | E37: EH | U37: A | V37: A | W37: 2 | X37: 2 | Y37: 2 | Z37: 2 | AB37: 2 | AC37: 2 | AD37: 2 | AJ37: 2 | AL37: 2 | AM37: 2 | AN37: 2 | AO37: 2 | AP37: 6 | AQ37: 2 | AR37: 2 | AS37: 2 | AT37: 2 | AU37: 2 | AV37: 2 | AW37: 6 | AX37: 2 | AY37: 2 | AZ37: 2 | BA37: 2 | BB37: 2 | BC37: 2 | BR37: =SUM(R37:BP37) -> 60 | BS37: =COUNTIF(F37:BP37,"A") -> 2
A38: 35 | B38: 154 | C38: LORIK NISHAD DASAI NISHAD | D38: PLASTER MASON | E38: EH | U38: 2 | V38: 2 | W38: 2 | X38: 2 | Y38: 2 | Z38: 2 | AB38: 2 | AC38: 2 | AD38: 2 | AJ38: 2 | AL38: 2 | AM38: 2 | AN38: 2 | AO38: 2 | AP38: 6 | AQ38: 2 | AR38: 2 | AS38: 2 | AT38: 2 | AU38: 2 | AV38: 2 | AX38: 2 | AY38: TR | AZ38: TR | BA38: TR | BB38: TR | BC38: TR | BR38: =SUM(R38:BP38) -> 48 | BS38: =COUNTIF(F38:BP38,"A") -> 0 | BT38: RED SEA to ROSHN on May.16 & Roshn to Lissen View June.14
A39: 36 | B39: 168 | C39: MUHAMMAD TOFIQUE MUHAMMAD SIDDIQUE | D39: BLOCK MASON | E39: EH | U39: 2 | V39: 2 | W39: 2 | X39: 2 | Y39: 2 | Z39: 2 | AB39: A | AC39: 2 | AD39: 2 | AJ39: 2 | AL39: 2 | AM39: 2 | AN39: 2 | AO39: 2 | AQ39: 2 | AR39: 2 | AS39: 2 | AT39: 2 | AU39: 2 | AV39: 2 | AW39: 6 | AX39: 2 | AY39: 2 | AZ39: 2 | BA39: 2 | BB39: 2 | BC39: 2 | BR39: =SUM(R39:BP39) -> 56 | BS39: =COUNTIF(F39:BP39,"A") -> 1
A40: 37 | B40: 170 | C40: SAQIB REHMAN DLPAZEER AHMED | D40: PLUMBER | E40: EH | U40: 2 | V40: 2 | W40: 2 | X40: 2 | Y40: 2 | Z40: S | AB40: 2 | AC40: 2 | AD40: 2 | AJ40: 2 | AL40: 2 | AM40: 2 | AN40: 2 | AO40: 2 | AQ40: 2 | AR40: 2 | AS40: A | AT40: 2 | AU40: 2 | AV40: 2 | AX40: 2 | AY40: 2 | AZ40: 2 | BA40: 2 | BB40: 2 | BC40: 2 | BR40: =SUM(R40:BP40) -> 48 | BS40: =COUNTIF(F40:BP40,"A") -> 1
...

Sheet MONTH SETTING
A1: MONTHS
A2: JANUARY | F2: FROM MONTH OF | G2: MAY
A3: FEBRUARY | F3: STARTING DATE | G3: =DATE(2026, MONTH(DATEVALUE("1"&G2)), DAY(DATEVALUE("1"&G2))) -> 46143
A4: MARCH | F4: Ending Date | G4: =EOMONTH(G3,0) -> 46173
A5: APRIL
A6: MAY | F6: TO | G6: JUNE
A7: JUNE | F7: STARTING DATE | G7: =DATE(2026, MONTH(DATEVALUE("1"&G6)), DAY(DATEVALUE("1"&G6))) -> 46174
A8: JULY | F8: Ending Date | G8: =EOMONTH(G7,0) -> 46203
A9: AUGUST
A10: SEPTEMBER
A11: OCTOBER
A12: NOVEMBER
A13: DECEMBER
